Workbook

Sheet 1. Cover
A1: TCOM — Trip.com Group Ltd (NasdaqGS:TCOM / SEHK:9961)
A2: Forward P/E scenario model — EPS x exit multiple (no DCF: payoff is a multiple re-rate)
A4: Valuation date | B4: 2026-06-14
A5: Working currency | B5: RMB (reporting)
A6: Output currency | B6: USD / ADS
A7: FX (RMB per USD) | B7: 6.76
A8: Spot price (USD) | B8: 46.47
A9: Spot date | B9: 2026-06-12
A11: Key outputs — FY2027E price target
A12: Scenario | B12: PT (USD) | C12: vs Spot | D12: Exit P/E
A13: Bear (take x0.80) | B13: ='4. Scenarios'!D34 -> 32.262102 | C13: =B13/$B$8-1 -> -0.30574345 | D13: ='4. Scenarios'!D31 -> 10
A14: Base (take x0.90) | B14: ='4. Scenarios'!C34 -> 61.172382 | C14: =B14/$B$8-1 -> 0.31638437 | D14: ='4. Scenarios'!C31 -> 15
A15: Bull (take x1.00) | B15: ='4. Scenarios'!E34 -> 86.099421 | C15: =B15/$B$8-1 -> 0.8527958 | D15: ='4. Scenarios'!E31 -> 18
A17: Asymmetric payoff (FY2027E)
A18: Upside = (Bull-Spot)/Spot | B18: =B15/$B$8-1 -> 0.8527958
A19: Downside = (Spot-Bear)/Spot | B19: =1-B13/$B$8 -> 0.30574345
A20: Skew (Up / Down) | B20: =B18/B19 -> 2.7892529
A22: Methodology
A23: - Revenue: 5 segments grown off FY25A volume; SAMR remedy = take multiplier on China accommodation (~80% of accom).
A24: - Costs: gross MARGIN driver (~80.5%, structurally stable); product-dev / G&A / S&M as TRENDING % of volume (op leverage).
A25: - Take cut flows ~1:1 to operating income (COGS & opex are volume-driven, not commission-rate-driven).
A26: - Below-the-line: recurring net interest + equity affiliates only. One-off investment gains EXCLUDED.
A27: - Valuation: forward EPS x exit P/E (lead) + EV/EBITDA cross-check. Output US$/ADS at FX 6.76 (current spot).
A29: Pillars (working/pillars_audited.md)
A30: P1 - International inflection, inbound-led (offensive) -> S&M lever
A31: P2 - China-core durability vs Meituan/Douyin/AI (defensive) -> defends the base
A32: Thesis-level: SAMR remedy is absorbable, not structural -> take lever + exit multiple
A34: Counter-pillars (working/risks.md)
A35: CP1 severe structural take compression (bear) | CP2 intl never inflects | CP3 competitive/AI erosion

Sheet 2. Assumptions
A1: TCOM — Assumptions & Drivers (RMB M unless noted)
A2: Blue = hard input. Black = formula. Every input justified in the Notes column.
A3: Driver | B3: FY2022A | C3: FY2023A | D3: FY2024A | E3: FY2025A | F3: FY2026E | G3: FY2027E | H3: Notes / source
A4: SEGMENT REVENUE — base volume (pre-remedy)
A5: Accommodation | B5: 7400 | C5: 17257 | D5: 21612 | E5: 26100 | F5: =E5*(1+F6) -> 29754 | G5: =F5*(1+G6) -> 33622.02 | H5: Disclosed: FY22 7,400 [20-F FY23] / FY23 17,257 / FY24 21,612 / FY25 26,100 [20-F FY25 Item8]. Fwd col = volume growth only (SAMR take applied separately below).
A6: growth (rev hist / vol fwd) | C6: =C5/B5-1 -> 1.332027 | D6: =D5/C5-1 -> 0.25236136 | E6: =E5/D5-1 -> 0.20766241 | F6: 0.14 | G6: 0.13 | H6: Hist accom REV +133/+25/+21% (decelerating; FY25 cadence Q1+23->Q2+21->FY+21). Fwd = +14/+13% VOLUME. 2026 proxy (no TCOM qtr yet, Q1 prints Jun-24): May-Day-2026 domestic trips +3.6%, but H World room-nights +13.6% YoY [Xinhua / H World] -> broad boom over, hotels still low-teens; +14% = hotel demand + intl/inbound mix. Take handled separately.
A7: Transportation | B7: 8253 | C7: 18443 | D7: 20301 | E7: 22489 | F7: =E7*(1+F8) -> 24513.01 | G7: =F7*(1+G8) -> 26474.051 | H7: Disclosed: FY22 8,253 / FY23 18,443 / FY24 20,301 / FY25 22,489 [20-F]. Mature, thin regulated take (air/rail).
A8: growth | C8: =C7/B7-1 -> 1.2347025 | D8: =D7/C7-1 -> 0.10074283 | E8: =E7/D7-1 -> 0.10777794 | F8: 0.09 | G8: 0.08 | H8: Hist computed; fwd +9/+8% (decelerating, volume-led).
A9: Packaged tours | B9: 781 | C9: 3140 | D9: 4336 | E9: 4688 | F9: =E9*(1+F10) -> 5250.56 | G9: =F9*(1+G10) -> 5775.616 | H9: Disclosed: FY22 781 (COVID) / FY23 3,140 / FY24 4,336 / FY25 4,688 [20-F]. Outbound recovery still completing.
A10: growth | C10: =C9/B9-1 -> 3.0204866 | D10: =D9/C9-1 -> 0.38089172 | E10: =E9/D9-1 -> 0.081180812 | F10: 0.12 | G10: 0.1 | H10: Hist computed; fwd +12/+10% (outbound re-rate).
A11: Corporate travel | B11: 1079 | C11: 2254 | D11: 2502 | E11: 2829 | F11: =E11*(1+F12) -> 3168.48 | G11: =F11*(1+G12) -> 3517.0128 | H11: Disclosed: FY22 1,079 / FY23 2,254 / FY24 2,502 / FY25 2,829 [20-F]. Share gains vs legacy TMCs.
A12: growth | C12: =C11/B11-1 -> 1.0889713 | D12: =D11/C11-1 -> 0.11002662 | E12: =E11/D11-1 -> 0.13069544 | F12: 0.12 | G12: 0.11 | H12: Hist computed; fwd +12/+11% (steady share gain).
A13: Other (ads, fin, SkyS) | B13: 2526 | C13: 3416 | D13: 4543 | E13: 6303 | F13: =E13*(1+F14) -> 8067.84 | G13: =F13*(1+G14) -> 10004.122 | H13: Other = total - 4 named segments: FY22 2,526 / FY23 3,416 / FY24 4,543 / FY25 6,303 [20-F, reconciled]. Ads + fin svcs + Skyscanner.
A14: growth | C14: =C13/B13-1 -> 0.35233571 | D14: =D13/C13-1 -> 0.32991803 | E14: =E13/D13-1 -> 0.3874092 | F14: 0.28 | G14: 0.24 | H14: Hist +35/+33/+39%; fwd +28/+24% — stays the fastest line (ads+fintech+Skyscanner ramping); modest decel for base effect + some SAMR cap on ad/ranking fees.
A15: Total revenue — base volume | B15: =SUM(B5,B7,B9,B11,B13) -> 20039 | C15: =SUM(C5,C7,C9,C11,C13) -> 44510 | D15: =SUM(D5,D7,D9,D11,D13) -> 53294 | E15: =SUM(E5,E7,E9,E11,E13) -> 62409 | F15: =SUM(F5,F7,F9,F11,F13) -> 70753.89 | G15: =SUM(G5,G7,G9,G11,G13) -> 79392.821 | H15: Revenue at unchanged commission rates (the volume the business processes). SAMR remedy applied next.
A16: SAMR REMEDY — China-accommodation take multiplier
A17: China-DOMESTIC accom share (SAMR-exposed) | B17: 0.86 | C17: 0.84 | D17: 0.82 | E17: 0.8 | F17: 0.8 | G17: 0.78 | H17: SIZED VIA GMV METHOD [est]: domestic hotel GMV ~RMB280bn [CBNData] x ~7.5% domestic take = ~RMB21bn = ~80% of the RMB26.1bn accom line (FY25). Declines as intl/outbound accom grow faster. Only DOMESTIC China hotels are SAMR-exposed (outbound on Ctrip + Trip.com intl are not). TCOM discloses neither take nor domestic split; GMV-anchored is the better of two soft estimates.
A18: China-domestic accom (exposed base) | B18: =B5*B17 -> 6364 | C18: =C5*C17 -> 14495.88 | D18: =D5*D17 -> 17721.84 | E18: =E5*E17 -> 20880 | F18: =F5*F17 -> 23803.2 | G18: =G5*G17 -> 26225.176 | H18: The revenue base on which the commission-rate remedy bites.
A19: Commission take multiplier (BASE) | B19: 1 | C19: 1 | D19: 1 | E19: 1 | F19: 0.95 | G19: 0.9 | H19: GLIDE PATH, not an instant step: probe still OPEN Jun-2026 + FY26 ~half elapsed -> FY26 only -5% (x0.95); FY27 = first full remedy year -> -10% steady state (x0.90); FY28 holds. Channel = commission caps / end-二选一 (Alibaba-2021, Meituan-2021 precedent). Bull x1.00 (behavioral-only) / Bear x0.90->0.80 on Scenarios tab.
A20: implied commission-rate cut | B20: 0 | C20: 0 | D20: 0 | E20: 0 | F20: =1-F19 -> 0.05 | G20: =1-G19 -> 0.1 | H20: The % haircut to the take rate (not to volume).
A21: Lost commission revenue (give-back) | B21: 0 | C21: 0 | D21: 0 | E21: 0 | F21: =F18*(1-F19) -> 1190.16 | G21: =G18*(1-G19) -> 2622.5176
A22: NET REVENUE (reported basis) | B22: =B15-B21 -> 20039 | C22: =C15-C21 -> 44510 | D22: =D15-D21 -> 53294 | E22: =E15-E21 -> 62409 | F22: =F15-F21 -> 69563.73 | G22: =G15-G21 -> 76770.304
A23: total revenue y/y growth | C23: =C22/B22-1 -> 1.2211687 | D23: =D22/C22-1 -> 0.19734891 | E23: =E22/D22-1 -> 0.17103239 | F23: =F22/E22-1 -> 0.1146426 | G23: =G22/F22-1 -> 0.10359671 | H23: Hist +122.1% (FY23 reopening) / +19.7% / +17.1%. Fwd ~+9% / +10% (volume net of base-case take cut).
A24: MARGINS
A25: Gross margin % (structural, pre-remedy) | B25: 0.775 | C25: 0.818 | D25: 0.812 | E25: 0.806 | F25: 0.805 | G25: 0.805 | H25: This is the cost-structure margin on VOLUME (COGS = payment+service). Hist 77.5/81.8/81.2/80.6%, held ~80.5%. REALISED GM (Income Statement) is LOWER in remedy years because the commission give-back cuts revenue, not cost - that gap IS the take-rate hit, by design, not an error.
A26: Cost of revenue (volume) | B26: =B15*(1-B25) -> 4508.775 | C26: =C15*(1-C25) -> 8100.82 | D26: =D15*(1-D25) -> 10019.272 | E26: =E15*(1-E25) -> 12107.346 | F26: =F15*(1-F25) -> 13797.009 | G26: =G15*(1-G25) -> 15481.6 | H26: Driven off BASE VOLUME (room-nights served), not commission rate -> a take cut does NOT shrink COGS.
A27: Gross profit | B27: =B22-B26 -> 15530.225 | C27: =C22-C26 -> 36409.18 | D27: =D22-D26 -> 43274.728 | E27: =E22-E26 -> 50301.654 | F27: =F22-F26 -> 55766.721 | G27: =G22-G26 -> 61288.704
A28: OPERATING EXPENSES — % of base-volume revenue (TRENDING)
A29: Product development % | B29: 0.416 | C29: 0.272 | D29: 0.247 | E29: 0.242 | F29: 0.235 | G29: 0.23 | H29: Hist 41.6/27.2/24.7/24.2% - steady operating leverage on a largely-fixed engineering base. Fwd 23.5/23.0%.
A30: Product development | B30: =B15*B29 -> 8336.224 | C30: =C15*C29 -> 12106.72 | D30: =D15*D29 -> 13163.618 | E30: =E15*E29 -> 15102.978 | F30: =F15*F29 -> 16627.164 | G30: =G15*G29 -> 18260.349 | H30: On base volume (R&D scales with product, not commission rate).
A31: Sales & marketing % (BASE) | B31: 0.212 | C31: 0.207 | D31: 0.223 | E31: 0.239 | F31: 0.24 | G31: 0.235 | H31: Hist 21.2/20.7/22.3/23.9% - RISING on intl reinvestment (the P1 margin drag). BASE 24.0->23.5% (intl begins to leverage). Bull 23.0/22.0% (intl inflects) / Bear 25.5/26.0% (perpetual sink) on Scenarios tab. This is the international lever.
A32: Sales & marketing | B32: =B15*B31 -> 4248.268 | C32: =C15*C31 -> 9213.57 | D32: =D15*D31 -> 11884.562 | E32: =E15*E31 -> 14915.751 | F32: =F15*F31 -> 16980.934 | G32: =G15*G31 -> 18657.313 | H32: On base volume.
A33: G&A % | B33: 0.142 | C33: 0.084 | D33: 0.077 | E33: 0.072 | F33: 0.07 | G33: 0.068 | H33: Hist 14.2/8.4/7.7/7.2% - declining, fixed-cost leverage. Fwd 7.0/6.8%.
A34: G&A | B34: =B15*B33 -> 2845.538 | C34: =C15*C33 -> 3738.84 | D34: =D15*D33 -> 4103.638 | E34: =E15*E33 -> 4493.448 | F34: =F15*F33 -> 4952.7723 | G34: =G15*G33 -> 5398.7118 | H34: On base volume.
A35: Total operating expense | B35: =B30+B32+B34 -> 15430.03 | C35: =C30+C32+C34 -> 25059.13 | D35: =D30+D32+D34 -> 29151.818 | E35: =E30+E32+E34 -> 34512.177 | F35: =F30+F32+F34 -> 38560.87 | G35: =G30+G32+G34 -> 42316.374 | H35: Ties FY22-25 actuals (15,438/25,065/29,127/34,514).
A36: Operating income | B36: =B27-B35 -> 100.195 | C36: =C27-C35 -> 11350.05 | D36: =D27-D35 -> 14122.91 | E36: =E27-E35 -> 15789.477 | F36: =F27-F35 -> 17205.851 | G36: =G27-G35 -> 18972.33 | H36: Ties FY22-25 actuals (88/11,324/14,177/15,773).
A37: operating margin | B37: =B36/B22 -> 0.005 | C37: =C36/C22 -> 0.255 | D37: =D36/D22 -> 0.265 | E37: =E36/E22 -> 0.253 | F37: =F36/F22 -> 0.2473394 | G37: =G36/G22 -> 0.2471311 | H37: Realised on reported revenue.
A38: BELOW THE LINE (recurring only; one-off gains excluded)
A39: Net interest income | B39: 585 | C39: 200 | D39: 776 | E39: 2154 | F39: 2400 | G39: 2600 | H39: Interest income - expense. Hist 585/200/776/2,154. Rising on RMB105.8bn cash+investments (20-F). Fwd 2,400/2,600.
A40: Income from affiliates | B40: -586 | C40: 1072 | D40: 2828 | E40: 353 | F40: 500 | G40: 600 | H40: Equity-method (MMYT/Tongcheng/etc). Volatile hist; fwd conservative 500/600 (vs FY24 2,828, FY25 353).
...

Sheet 3. Income Statement
A1: TCOM — Income Statement (RMB M) — BASE case
A2: FY2022A-FY2025A = CapIQ actuals (saved export). FY2026E-FY2027E = formulas off the Assumptions tab.
B3: FY2022A | C3: FY2023A | D3: FY2024A | E3: FY2025A | F3: FY2026E | G3: FY2027E
A4: Total revenue (gross, pre-remedy) | B4: ='2. Assumptions'!B15 -> 20039 | C4: ='2. Assumptions'!C15 -> 44510 | D4: ='2. Assumptions'!D15 -> 53294 | E4: ='2. Assumptions'!E15 -> 62409 | F4: ='2. Assumptions'!F15 -> 70753.89 | G4: ='2. Assumptions'!G15 -> 79392.821 | H4: =base-volume bookings at unchanged rates -> #NAME?
A5: less: SAMR commission give-back | B5: =-'2. Assumptions'!B21 -> 0 | C5: =-'2. Assumptions'!C21 -> 0 | D5: =-'2. Assumptions'!D21 -> 0 | E5: =-'2. Assumptions'!E21 -> 0 | F5: =-'2. Assumptions'!F21 -> -1190.16 | G5: =-'2. Assumptions'!G21 -> -2622.5176 | H5: 0 historically (pre-remedy)
A6: Net revenue (reported basis) | B6: ='2. Assumptions'!B22 -> 20039 | C6: ='2. Assumptions'!C22 -> 44510 | D6: ='2. Assumptions'!D22 -> 53294 | E6: ='2. Assumptions'!E22 -> 62409 | F6: ='2. Assumptions'!F22 -> 69563.73 | G6: ='2. Assumptions'!G22 -> 76770.304
A7: y/y growth | C7: =C6/B6-1 -> 1.2211687 | D7: =D6/C6-1 -> 0.19734891 | E7: =E6/D6-1 -> 0.17103239 | F7: =F6/E6-1 -> 0.1146426 | G7: =G6/F6-1 -> 0.10359671
A8: Cost of revenue (= struct rate x volume) | B8: ='2. Assumptions'!B26 -> 4508.775 | C8: ='2. Assumptions'!C26 -> 8100.82 | D8: ='2. Assumptions'!D26 -> 10019.272 | E8: ='2. Assumptions'!E26 -> 12107.346 | F8: ='2. Assumptions'!F26 -> 13797.009 | G8: ='2. Assumptions'!G26 -> 15481.6 | H8: on VOLUME -> a take cut doesn't shrink it
A9: Gross profit | B9: ='2. Assumptions'!B27 -> 15530.225 | C9: ='2. Assumptions'!C27 -> 36409.18 | D9: ='2. Assumptions'!D27 -> 43274.728 | E9: ='2. Assumptions'!E27 -> 50301.654 | F9: ='2. Assumptions'!F27 -> 55766.721 | G9: ='2. Assumptions'!G27 -> 61288.704
A10: gross margin (realised) | B10: =B9/B6 -> 0.775 | C10: =C9/C6 -> 0.818 | D10: =D9/D6 -> 0.812 | E10: =E9/E6 -> 0.806 | F10: =F9/F6 -> 0.80166376 | G10: =G9/G6 -> 0.79833869 | H10: OUTPUT - below structural in remedy yrs
A11: memo: structural GM (pre-remedy) | B11: ='2. Assumptions'!B25 -> 0.775 | C11: ='2. Assumptions'!C25 -> 0.818 | D11: ='2. Assumptions'!D25 -> 0.812 | E11: ='2. Assumptions'!E25 -> 0.806 | F11: ='2. Assumptions'!F25 -> 0.805 | G11: ='2. Assumptions'!G25 -> 0.805 | H11: the 80.5% INPUT. Realised is lower BY give-back/rev - that gap IS the take cut, not an error.
A12: Product development | B12: ='2. Assumptions'!B30 -> 8336.224 | C12: ='2. Assumptions'!C30 -> 12106.72 | D12: ='2. Assumptions'!D30 -> 13163.618 | E12: ='2. Assumptions'!E30 -> 15102.978 | F12: ='2. Assumptions'!F30 -> 16627.164 | G12: ='2. Assumptions'!G30 -> 18260.349
A13: Sales & marketing | B13: ='2. Assumptions'!B32 -> 4248.268 | C13: ='2. Assumptions'!C32 -> 9213.57 | D13: ='2. Assumptions'!D32 -> 11884.562 | E13: ='2. Assumptions'!E32 -> 14915.751 | F13: ='2. Assumptions'!F32 -> 16980.934 | G13: ='2. Assumptions'!G32 -> 18657.313 | H13: the international lever
A14: General & administrative | B14: ='2. Assumptions'!B34 -> 2845.538 | C14: ='2. Assumptions'!C34 -> 3738.84 | D14: ='2. Assumptions'!D34 -> 4103.638 | E14: ='2. Assumptions'!E34 -> 4493.448 | F14: ='2. Assumptions'!F34 -> 4952.7723 | G14: ='2. Assumptions'!G34 -> 5398.7118
A15: Total operating expense | B15: ='2. Assumptions'!B35 -> 15430.03 | C15: ='2. Assumptions'!C35 -> 25059.13 | D15: ='2. Assumptions'!D35 -> 29151.818 | E15: ='2. Assumptions'!E35 -> 34512.177 | F15: ='2. Assumptions'!F35 -> 38560.87 | G15: ='2. Assumptions'!G35 -> 42316.374
A16: Operating income (EBIT) | B16: ='2. Assumptions'!B36 -> 100.195 | C16: ='2. Assumptions'!C36 -> 11350.05 | D16: ='2. Assumptions'!D36 -> 14122.91 | E16: ='2. Assumptions'!E36 -> 15789.477 | F16: ='2. Assumptions'!F36 -> 17205.851 | G16: ='2. Assumptions'!G36 -> 18972.33
A17: operating margin | B17: =B16/B6 -> 0.005 | C17: =C16/C6 -> 0.255 | D17: =D16/D6 -> 0.265 | E17: =E16/E6 -> 0.253 | F17: =F16/F6 -> 0.2473394 | G17: =G16/G6 -> 0.2471311
A18: Net interest income | B18: ='2. Assumptions'!B39 -> 585 | C18: ='2. Assumptions'!C39 -> 200 | D18: ='2. Assumptions'!D39 -> 776 | E18: ='2. Assumptions'!E39 -> 2154 | F18: ='2. Assumptions'!F39 -> 2400 | G18: ='2. Assumptions'!G39 -> 2600
A19: Income from affiliates | B19: ='2. Assumptions'!B40 -> -586 | C19: ='2. Assumptions'!C40 -> 1072 | D19: ='2. Assumptions'!D40 -> 2828 | E19: ='2. Assumptions'!E40 -> 353 | F19: ='2. Assumptions'!F40 -> 500 | G19: ='2. Assumptions'!G40 -> 600
A20: Pretax income (ex one-off) | B20: ='2. Assumptions'!B42 -> 99.195 | C20: ='2. Assumptions'!C42 -> 12622.05 | D20: ='2. Assumptions'!D42 -> 17726.91 | E20: ='2. Assumptions'!E42 -> 18296.477 | F20: ='2. Assumptions'!F42 -> 20105.851 | G20: ='2. Assumptions'!G42 -> 22172.33
A21: Tax | B21: =-'2. Assumptions'!B42*'2. Assumptions'!B43 -> -32.73435 | C21: =-'2. Assumptions'!C42*'2. Assumptions'!C43 -> -1893.3075 | D21: =-'2. Assumptions'!D42*'2. Assumptions'!D43 -> -2304.4983 | E21: =-'2. Assumptions'!E42*'2. Assumptions'!E43 -> -2744.4716 | F21: =-'2. Assumptions'!F42*'2. Assumptions'!F43 -> -3015.8777 | G21: =-'2. Assumptions'!G42*'2. Assumptions'!G43 -> -3325.8495
A22: Minority interest | B22: ='2. Assumptions'!B44 -> 36 | C22: ='2. Assumptions'!C44 -> -84 | D22: ='2. Assumptions'!D44 -> -160 | E22: ='2. Assumptions'!E44 -> -92 | F22: ='2. Assumptions'!F44 -> -100 | G22: ='2. Assumptions'!G44 -> -100
A23: Net income (clean, ex one-off) | B23: ='2. Assumptions'!B45 -> 102.46065 | C23: ='2. Assumptions'!C45 -> 10644.742 | D23: ='2. Assumptions'!D45 -> 15262.412 | E23: ='2. Assumptions'!E45 -> 15460.005 | F23: ='2. Assumptions'!F45 -> 16989.974 | G23: ='2. Assumptions'!G45 -> 18746.48
A24: Diluted ADS (M) | B24: ='2. Assumptions'!B47 -> 657 | C24: ='2. Assumptions'!C47 -> 671 | D24: ='2. Assumptions'!D47 -> 689 | E24: ='2. Assumptions'!E47 -> 698 | F24: ='2. Assumptions'!F47 -> 690 | G24: ='2. Assumptions'!G47 -> 680
A25: EPS — clean (RMB) | B25: ='2. Assumptions'!B48 -> 0.15595228 | C25: ='2. Assumptions'!C48 -> 15.863998 | D25: ='2. Assumptions'!D48 -> 22.151541 | E25: ='2. Assumptions'!E48 -> 22.149005 | F25: ='2. Assumptions'!F48 -> 24.62315 | G25: ='2. Assumptions'!G48 -> 27.568353
A26: EPS y/y growth (clean) | C26: =IFERROR(C25/B25-1,"nm") -> 100.72341 | D26: =IFERROR(D25/C25-1,"nm") -> 0.3963404 | E26: =IFERROR(E25/D25-1,"nm") -> -0.00011448351 | F26: =IFERROR(F25/E25-1,"nm") -> 0.11170458 | G26: =IFERROR(G25/F25-1,"nm") -> 0.11961114 | H26: operating EPS growth (ex one-off)
A28: memo: one-off investment gain (excluded) | B28: ='2. Assumptions'!B41 -> 2165 | C28: ='2. Assumptions'!C41 -> -1003 | D28: ='2. Assumptions'!D41 -> 1759 | E28: ='2. Assumptions'!E41 -> 20812 | F28: ='2. Assumptions'!F41 -> 0 | G28: ='2. Assumptions'!G41 -> 0
A29: memo: reported NI (clean + one-off, after tax) | B29: =B23+'2. Assumptions'!B41*(1-'2. Assumptions'!B43) -> 1553.0107 | C29: =C23+'2. Assumptions'!C41*(1-'2. Assumptions'!C43) -> 9792.1925 | D29: =D23+'2. Assumptions'!D41*(1-'2. Assumptions'!D43) -> 16792.742 | E29: =E23+'2. Assumptions'!E41*(1-'2. Assumptions'!E43) -> 33150.205 | F29: =F23+'2. Assumptions'!F41*(1-'2. Assumptions'!F43) -> 16989.974 | G29: =G23+'2. Assumptions'!G41*(1-'2. Assumptions'!G43) -> 18746.48
A31: FY25 ties: rev 62,409 / OI 15,773 / clean NI ~15.5bn ~= co. non-GAAP ex-gain. Reported NI 33,294 incl RMB19.9bn one-off.
A33: Historical growth (YoY %) | C33: FY2023A | D33: FY2024A | E33: FY2025A | F33: comment
A34: Total revenue | C34: 1.221 | D34: 0.197 | E34: 0.171 | F34: +122% reopening -> normalising to mid-teens
A35: Gross profit | C35: 1.344 | D35: 0.19 | E35: 0.161 | F35: tracks revenue; GM stable ~81%
A36: Product development | C36: 0.453 | D36: 0.084 | E36: 0.152 | F36: leverages then steps up FY25
A37: Sales & marketing | C37: 1.165 | D37: 0.293 | E37: 0.252 | F37: RISES faster than revenue = the intl drag
A38: G&A | C38: 0.315 | D38: 0.092 | E38: 0.095 | F38: slowest line; fixed-cost leverage
A39: Operating income | C39: nm | D39: 0.252 | E39: 0.113 | F39: FY25 +11.3% < rev +17.1% -> margin compressed (S&M)
A40: Net income (reported) | C40: 6.069 | D40: 0.721 | E40: 0.951 | F40: DISTORTED by one-off investment gains, not operating
A41: Diluted EPS (reported) | C41: 5.907 | D41: 0.677 | E41: 0.924 | F41: same one-off distortion; clean EPS grows mid-teens

Sheet 4. Scenarios
A1: TCOM — Scenarios (the cases): price target under each
A2: Levers flex: (1) take multiplier — a GLIDE PATH (remedy phases in, not an instant step), (2) S&M ratio, (3) exit P/E.
A4: Lever | C4: BASE | D4: BEAR | E4: BULL | F4: Justification
A5: (1a) China-accom take mult — FY26 | C5: 0.95 | D5: 0.9 | E5: 1 | F5: FY26 ~half elapsed + ruling still pending -> only partial impact: Base -5% / Bear -10% / Bull 0%.
A6: (1b) China-accom take mult — FY27 | C6: 0.9 | D6: 0.8 | E6: 1 | F6: FY27 = first full remedy year -> reaches steady state: Base -10% / Bear -20% / Bull 0% (behavioral-only). FY28 holds.
A7: (2) S&M % — FY26 | C7: 0.24 | D7: 0.255 | E7: 0.23
A8: (2) S&M % — FY27 | C8: 0.235 | D8: 0.26 | E8: 0.22 | F8: Base modest leverage / Bear perpetual sink (CP2) / Bull intl inflects (P1). <- this is Pillar 1 in the model.
A9: (3) Exit P/E | C9: 15 | D9: 10 | E9: 18 | F9: Bear=10x (BELOW current trough 12.4x -> deep-stress, toward China-internet lows / Tongcheng 7x) / Base~Booking 15.3x / Bull=TCOM pre-shock 18.3x.
A11: FY2026E build
A12: Net revenue | C12: ='2. Assumptions'!F15-'2. Assumptions'!F18*(1-C5) -> 69563.73 | D12: ='2. Assumptions'!F15-'2. Assumptions'!F18*(1-D5) -> 68373.57 | E12: ='2. Assumptions'!F15-'2. Assumptions'!F18*(1-E5) -> 70753.89
A13: Gross profit | C13: =C12-'2. Assumptions'!F26 -> 55766.721 | D13: =D12-'2. Assumptions'!F26 -> 54576.561 | E13: =E12-'2. Assumptions'!F26 -> 56956.881
A14: Product development | C14: ='2. Assumptions'!F30 -> 16627.164 | D14: ='2. Assumptions'!F30 -> 16627.164 | E14: ='2. Assumptions'!F30 -> 16627.164
A15: Sales & marketing | C15: ='2. Assumptions'!F15*C7 -> 16980.934 | D15: ='2. Assumptions'!F15*D7 -> 18042.242 | E15: ='2. Assumptions'!F15*E7 -> 16273.395
A16: G&A | C16: ='2. Assumptions'!F34 -> 4952.7723 | D16: ='2. Assumptions'!F34 -> 4952.7723 | E16: ='2. Assumptions'!F34 -> 4952.7723
A17: Operating income | C17: =C13-C14-C15-C16 -> 17205.851 | D17: =D13-D14-D15-D16 -> 14954.383 | E17: =E13-E14-E15-E16 -> 19103.55
A18: operating margin | C18: =C17/C12 -> 0.2473394 | D18: =D17/D12 -> 0.21871584 | E18: =E17/E12 -> 0.27
A19: Pretax (ex one-off) | C19: =C17+'2. Assumptions'!F39+'2. Assumptions'!F40 -> 20105.851 | D19: =D17+'2. Assumptions'!F39+'2. Assumptions'!F40 -> 17854.383 | E19: =E17+'2. Assumptions'!F39+'2. Assumptions'!F40 -> 22003.55
A20: Net income (clean) | C20: =C19*(1-'2. Assumptions'!F43)+'2. Assumptions'!F44 -> 16989.974 | D20: =D19*(1-'2. Assumptions'!F43)+'2. Assumptions'!F44 -> 15076.226 | E20: =E19*(1-'2. Assumptions'!F43)+'2. Assumptions'!F44 -> 18603.018
A21: EPS (RMB) | C21: =C20/'2. Assumptions'!F47 -> 24.62315 | D21: =D20/'2. Assumptions'!F47 -> 21.849602 | E21: =E20/'2. Assumptions'!F47 -> 26.960895
A23: FY2027E build
A24: Net revenue | C24: ='2. Assumptions'!G15-'2. Assumptions'!G18*(1-C6) -> 76770.304 | D24: ='2. Assumptions'!G15-'2. Assumptions'!G18*(1-D6) -> 74147.786 | E24: ='2. Assumptions'!G15-'2. Assumptions'!G18*(1-E6) -> 79392.821
A25: Gross profit | C25: =C24-'2. Assumptions'!G26 -> 61288.704 | D25: =D24-'2. Assumptions'!G26 -> 58666.186 | E25: =E24-'2. Assumptions'!G26 -> 63911.221
A26: Sales & marketing | C26: ='2. Assumptions'!G15*C8 -> 18657.313 | D26: ='2. Assumptions'!G15*D8 -> 20642.134 | E26: ='2. Assumptions'!G15*E8 -> 17466.421
A27: Operating income | C27: =C25-'2. Assumptions'!G30-C26-'2. Assumptions'!G34 -> 18972.33 | D27: =D25-'2. Assumptions'!G30-D26-'2. Assumptions'!G34 -> 14364.992 | E27: =E25-'2. Assumptions'!G30-E26-'2. Assumptions'!G34 -> 22785.74
A28: operating margin | C28: =C27/C24 -> 0.2471311 | D28: =D27/D24 -> 0.1937346 | E28: =E27/E24 -> 0.287
A29: Net income (clean) | C29: =(C27+'2. Assumptions'!G39+'2. Assumptions'!G40)*(1-'2. Assumptions'!G43)+'2. Assumptions'!G44 -> 18746.48 | D29: =(D27+'2. Assumptions'!G39+'2. Assumptions'!G40)*(1-'2. Assumptions'!G43)+'2. Assumptions'!G44 -> 14830.243 | E29: =(E27+'2. Assumptions'!G39+'2. Assumptions'!G40)*(1-'2. Assumptions'!G43)+'2. Assumptions'!G44 -> 21987.879
A30: EPS (RMB) | C30: =C29/'2. Assumptions'!G47 -> 27.568353 | D30: =D29/'2. Assumptions'!G47 -> 21.809181 | E30: =E29/'2. Assumptions'!G47 -> 32.335116
A31: Exit P/E | C31: =C9 -> 15 | D31: =D9 -> 10 | E31: =E9 -> 18
C32: BASE | D32: BEAR | E32: BULL
A33: FY2027E EPS (RMB) | C33: =C30 -> 27.568353 | D33: =D30 -> 21.809181 | E33: =E30 -> 32.335116
A34: PRICE TARGET (USD/ADS) | C34: =C30*C31/'2. Assumptions'!F49 -> 61.172382 | D34: =D30*D31/'2. Assumptions'!F49 -> 32.262102 | E34: =E30*E31/'2. Assumptions'!F49 -> 86.099421
A35: vs spot $46.47 | C35: =C34/46.47-1 -> 0.31638437 | D35: =D34/46.47-1 -> -0.30574345 | E35: =E34/46.47-1 -> 0.8527958
A36: FY2026E PT (USD) — checkpoint | C36: =C21*C31/'2. Assumptions'!F49 -> 54.637168 | D36: =D21*D31/'2. Assumptions'!F49 -> 32.321897 | E36: =E21*E31/'2. Assumptions'!F49 -> 71.789366
A37: Skew (FY27)
A38: Upside (Bull) | B38: =E35 -> 0.8527958
A39: Downside (Bear) | B39: =-D35 -> 0.30574345
A40: Skew (Up/Down) | B40: =E38/B39 -> 0
A42: Honest read: BASE prices a -10% China-accom commission cut at ~1:1 flow-through, so base rev ~5% and base NI ~11%
A43: below consensus (consensus prices little economic remedy). Bull (behavioral-only) lands ~at/above consensus. The skew is the thesis.
A45: Take-rate transparency & OI-margin bridge (FY2027E)
...

Sheet 5. Multiples
A1: Exit-multiple justification (NTM P/E)
A2: Payoff is a re-rate, so the exit P/E is the single biggest lever. Each case is anchored to a real reference.
A4: TCOM own NTM P/E history (CapIQ, quarterly avg)
A5: 2023-12 | B5: 15.2
A6: 2024-06 | B6: 18
A7: 2024-12 | B7: 19
A8: 2025-06 | B8: 17.1
A9: 2025-12 | B9: 18.3
A10: 2026-03 | B10: 14.2
A11: 2026-06 | B11: 12.4
A12: 3-yr mean ~16.5x | range 12.4-19.7x | pre-SAMR-shock (Dec-25) 18.3x | now 12.4x (trough)
A14: Peer NTM P/E (CapIQ)
A15: Booking (BKNG) | B15: 15.25
A16: Expedia (EXPE) | B16: 10.98
A17: Airbnb (ABNB) | B17: 25.32
A18: Tongcheng (0780) | B18: 7.25
A19: MakeMyTrip (MMYT) | B19: 78.2 (NM)
A20: OTA leaders cluster 11-15x (Booking/Expedia); China-internet complex compressed 8-13x.
A22: Chosen exit multiples
A23: Case | B23: P/E | C23: Anchor
A24: Bear | B24: 10
A25: Base | B25: 15 | C25: ~ Booking 15.3x; below TCOM 3-yr mean 16.5x. Modest normalisation.
A26: Bull | B26: 18
A28: Growth check: rev +12-13%, EPS mid-teens. PEG at 15x / ~14% ~= 1.1. Reasonable for dominant compounder.
A30: EV/EBITDA cross-check (FY2027E, base)
A31: Market cap (698M ADS x $46.47 x FX) | B31: =698*46.47*'2. Assumptions'!F49 -> 219267.77
A32: less: net cash (operating) | B32: -75000
A33: less: equity portfolio (MMYT/Tongcheng etc) | B33: -22000
A34: Enterprise value | B34: =B31+B32+B33 -> 122267.77
A35: FY2027E EBITDA (base OI + ~900 D&A) | B35: ='4. Scenarios'!C27+900 -> 19872.33
A36: EV/EBITDA (operating business) | B36: =B34/B35 -> 6.1526639
A37: vs Booking ~11.7x -> TCOM operating co ~7x = cheap
A38: Implied PT at 11x FY27 EBITDA + cash + portfolio (USD) | B38: =(B35*11-B32-B33)/680/'2. Assumptions'!F49 -> 68.655506
A39: above the P/E base -> P/E is the conservative lead; balance sheet = unpriced floor.

Sheet 6. Sensitivity
A1: Sensitivity — FY2027E PT (USD/ADS)
A3: PT = f(China-accom take multiplier, exit P/E). Other drivers at base; S&M base.
A5: take x / P/E -> | B5: 10 | C5: 12 | D5: 15 | E5: 16 | F5: 18
A6: x0.80 | B6: =(((('2. Assumptions'!G15-'2. Assumptions'!G18*(1-0.8)-'2. Assumptions'!G26-'2. Assumptions'!G30-'2. Assumptions'!G32-'2. Assumptions'!G34)+'2. Assumptions'!G39+'2. Assumptions'!G40)*(1-'2. Assumptions'!G43)+'2. Assumptions'!G44)/'2. Assumptions'!G47)*10/'2. Assumptions'!F49 -> 35.932258 | C6: =(((('2. Assumptions'!G15-'2. Assumptions'!G18*(1-0.8)-'2. Assumptions'!G26-'2. Assumptions'!G30-'2. Assumptions'!G32-'2. Assumptions'!G34)+'2. Assumptions'!G39+'2. Assumptions'!G40)*(1-'2. Assumptions'!G43)+'2. Assumptions'!G44)/'2. Assumptions'!G47)*12/'2. Assumptions'!F49 -> 43.11871 | D6: =(((('2. Assumptions'!G15-'2. Assumptions'!G18*(1-0.8)-'2. Assumptions'!G26-'2. Assumptions'!G30-'2. Assumptions'!G32-'2. Assumptions'!G34)+'2. Assumptions'!G39+'2. Assumptions'!G40)*(1-'2. Assumptions'!G43)+'2. Assumptions'!G44)/'2. Assumptions'!G47)*15/'2. Assumptions'!F49 -> 53.898387 | E6: =(((('2. Assumptions'!G15-'2. Assumptions'!G18*(1-0.8)-'2. Assumptions'!G26-'2. Assumptions'!G30-'2. Assumptions'!G32-'2. Assumptions'!G34)+'2. Assumptions'!G39+'2. Assumptions'!G40)*(1-'2. Assumptions'!G43)+'2. Assumptions'!G44)/'2. Assumptions'!G47)*16/'2. Assumptions'!F49 -> 57.491613 | F6: =(((('2. Assumptions'!G15-'2. Assumptions'!G18*(1-0.8)-'2. Assumptions'!G26-'2. Assumptions'!G30-'2. Assumptions'!G32-'2. Assumptions'!G34)+'2. Assumptions'!G39+'2. Assumptions'!G40)*(1-'2. Assumptions'!G43)+'2. Assumptions'!G44)/'2. Assumptions'!G47)*18/'2. Assumptions'!F49 -> 64.678065
A7: x0.85 | B7: =(((('2. Assumptions'!G15-'2. Assumptions'!G18*(1-0.85)-'2. Assumptions'!G26-'2. Assumptions'!G30-'2. Assumptions'!G32-'2. Assumptions'!G34)+'2. Assumptions'!G39+'2. Assumptions'!G40)*(1-'2. Assumptions'!G43)+'2. Assumptions'!G44)/'2. Assumptions'!G47)*10/'2. Assumptions'!F49 -> 38.356923 | C7: =(((('2. Assumptions'!G15-'2. Assumptions'!G18*(1-0.85)-'2. Assumptions'!G26-'2. Assumptions'!G30-'2. Assumptions'!G32-'2. Assumptions'!G34)+'2. Assumptions'!G39+'2. Assumptions'!G40)*(1-'2. Assumptions'!G43)+'2. Assumptions'!G44)/'2. Assumptions'!G47)*12/'2. Assumptions'!F49 -> 46.028308 | D7: =(((('2. Assumptions'!G15-'2. Assumptions'!G18*(1-0.85)-'2. Assumptions'!G26-'2. Assumptions'!G30-'2. Assumptions'!G32-'2. Assumptions'!G34)+'2. Assumptions'!G39+'2. Assumptions'!G40)*(1-'2. Assumptions'!G43)+'2. Assumptions'!G44)/'2. Assumptions'!G47)*15/'2. Assumptions'!F49 -> 57.535385 | E7: =(((('2. Assumptions'!G15-'2. Assumptions'!G18*(1-0.85)-'2. Assumptions'!G26-'2. Assumptions'!G30-'2. Assumptions'!G32-'2. Assumptions'!G34)+'2. Assumptions'!G39+'2. Assumptions'!G40)*(1-'2. Assumptions'!G43)+'2. Assumptions'!G44)/'2. Assumptions'!G47)*16/'2. Assumptions'!F49 -> 61.371077 | F7: =(((('2. Assumptions'!G15-'2. Assumptions'!G18*(1-0.85)-'2. Assumptions'!G26-'2. Assumptions'!G30-'2. Assumptions'!G32-'2. Assumptions'!G34)+'2. Assumptions'!G39+'2. Assumptions'!G40)*(1-'2. Assumptions'!G43)+'2. Assumptions'!G44)/'2. Assumptions'!G47)*18/'2. Assumptions'!F49 -> 69.042461
A8: x0.90 | B8: =(((('2. Assumptions'!G15-'2. Assumptions'!G18*(1-0.9)-'2. Assumptions'!G26-'2. Assumptions'!G30-'2. Assumptions'!G32-'2. Assumptions'!G34)+'2. Assumptions'!G39+'2. Assumptions'!G40)*(1-'2. Assumptions'!G43)+'2. Assumptions'!G44)/'2. Assumptions'!G47)*10/'2. Assumptions'!F49 -> 40.781588 | C8: =(((('2. Assumptions'!G15-'2. Assumptions'!G18*(1-0.9)-'2. Assumptions'!G26-'2. Assumptions'!G30-'2. Assumptions'!G32-'2. Assumptions'!G34)+'2. Assumptions'!G39+'2. Assumptions'!G40)*(1-'2. Assumptions'!G43)+'2. Assumptions'!G44)/'2. Assumptions'!G47)*12/'2. Assumptions'!F49 -> 48.937906 | D8: =(((('2. Assumptions'!G15-'2. Assumptions'!G18*(1-0.9)-'2. Assumptions'!G26-'2. Assumptions'!G30-'2. Assumptions'!G32-'2. Assumptions'!G34)+'2. Assumptions'!G39+'2. Assumptions'!G40)*(1-'2. Assumptions'!G43)+'2. Assumptions'!G44)/'2. Assumptions'!G47)*15/'2. Assumptions'!F49 -> 61.172382 | E8: =(((('2. Assumptions'!G15-'2. Assumptions'!G18*(1-0.9)-'2. Assumptions'!G26-'2. Assumptions'!G30-'2. Assumptions'!G32-'2. Assumptions'!G34)+'2. Assumptions'!G39+'2. Assumptions'!G40)*(1-'2. Assumptions'!G43)+'2. Assumptions'!G44)/'2. Assumptions'!G47)*16/'2. Assumptions'!F49 -> 65.250541 | F8: =(((('2. Assumptions'!G15-'2. Assumptions'!G18*(1-0.9)-'2. Assumptions'!G26-'2. Assumptions'!G30-'2. Assumptions'!G32-'2. Assumptions'!G34)+'2. Assumptions'!G39+'2. Assumptions'!G40)*(1-'2. Assumptions'!G43)+'2. Assumptions'!G44)/'2. Assumptions'!G47)*18/'2. Assumptions'!F49 -> 73.406858
A9: x0.95 | B9: =(((('2. Assumptions'!G15-'2. Assumptions'!G18*(1-0.95)-'2. Assumptions'!G26-'2. Assumptions'!G30-'2. Assumptions'!G32-'2. Assumptions'!G34)+'2. Assumptions'!G39+'2. Assumptions'!G40)*(1-'2. Assumptions'!G43)+'2. Assumptions'!G44)/'2. Assumptions'!G47)*10/'2. Assumptions'!F49 -> 43.206253 | C9: =(((('2. Assumptions'!G15-'2. Assumptions'!G18*(1-0.95)-'2. Assumptions'!G26-'2. Assumptions'!G30-'2. Assumptions'!G32-'2. Assumptions'!G34)+'2. Assumptions'!G39+'2. Assumptions'!G40)*(1-'2. Assumptions'!G43)+'2. Assumptions'!G44)/'2. Assumptions'!G47)*12/'2. Assumptions'!F49 -> 51.847503 | D9: =(((('2. Assumptions'!G15-'2. Assumptions'!G18*(1-0.95)-'2. Assumptions'!G26-'2. Assumptions'!G30-'2. Assumptions'!G32-'2. Assumptions'!G34)+'2. Assumptions'!G39+'2. Assumptions'!G40)*(1-'2. Assumptions'!G43)+'2. Assumptions'!G44)/'2. Assumptions'!G47)*15/'2. Assumptions'!F49 -> 64.809379 | E9: =(((('2. Assumptions'!G15-'2. Assumptions'!G18*(1-0.95)-'2. Assumptions'!G26-'2. Assumptions'!G30-'2. Assumptions'!G32-'2. Assumptions'!G34)+'2. Assumptions'!G39+'2. Assumptions'!G40)*(1-'2. Assumptions'!G43)+'2. Assumptions'!G44)/'2. Assumptions'!G47)*16/'2. Assumptions'!F49 -> 69.130005 | F9: =(((('2. Assumptions'!G15-'2. Assumptions'!G18*(1-0.95)-'2. Assumptions'!G26-'2. Assumptions'!G30-'2. Assumptions'!G32-'2. Assumptions'!G34)+'2. Assumptions'!G39+'2. Assumptions'!G40)*(1-'2. Assumptions'!G43)+'2. Assumptions'!G44)/'2. Assumptions'!G47)*18/'2. Assumptions'!F49 -> 77.771255
A10: x1.00 | B10: =(((('2. Assumptions'!G15-'2. Assumptions'!G18*(1-1)-'2. Assumptions'!G26-'2. Assumptions'!G30-'2. Assumptions'!G32-'2. Assumptions'!G34)+'2. Assumptions'!G39+'2. Assumptions'!G40)*(1-'2. Assumptions'!G43)+'2. Assumptions'!G44)/'2. Assumptions'!G47)*10/'2. Assumptions'!F49 -> 45.630918 | C10: =(((('2. Assumptions'!G15-'2. Assumptions'!G18*(1-1)-'2. Assumptions'!G26-'2. Assumptions'!G30-'2. Assumptions'!G32-'2. Assumptions'!G34)+'2. Assumptions'!G39+'2. Assumptions'!G40)*(1-'2. Assumptions'!G43)+'2. Assumptions'!G44)/'2. Assumptions'!G47)*12/'2. Assumptions'!F49 -> 54.757101 | D10: =(((('2. Assumptions'!G15-'2. Assumptions'!G18*(1-1)-'2. Assumptions'!G26-'2. Assumptions'!G30-'2. Assumptions'!G32-'2. Assumptions'!G34)+'2. Assumptions'!G39+'2. Assumptions'!G40)*(1-'2. Assumptions'!G43)+'2. Assumptions'!G44)/'2. Assumptions'!G47)*15/'2. Assumptions'!F49 -> 68.446377 | E10: =(((('2. Assumptions'!G15-'2. Assumptions'!G18*(1-1)-'2. Assumptions'!G26-'2. Assumptions'!G30-'2. Assumptions'!G32-'2. Assumptions'!G34)+'2. Assumptions'!G39+'2. Assumptions'!G40)*(1-'2. Assumptions'!G43)+'2. Assumptions'!G44)/'2. Assumptions'!G47)*16/'2. Assumptions'!F49 -> 73.009468 | F10: =(((('2. Assumptions'!G15-'2. Assumptions'!G18*(1-1)-'2. Assumptions'!G26-'2. Assumptions'!G30-'2. Assumptions'!G32-'2. Assumptions'!G34)+'2. Assumptions'!G39+'2. Assumptions'!G40)*(1-'2. Assumptions'!G43)+'2. Assumptions'!G44)/'2. Assumptions'!G47)*18/'2. Assumptions'!F49 -> 82.135652
A12: Base case = x0.90 take, 15x (highlighted). Top-left = bear corner, bottom-right = bull corner.
A14: Tornado — FY2027E PT swing (base $ +/- )
A15: 1. Exit P/E (the re-rate) 12x <-> 18x | B15: largest bar
A16: 2. China-accom take (SAMR) x0.80 <-> x1.00 | B16: 2nd; ~1:1 to OI
A17: 3. S&M ratio (intl margin) 26% <-> 22% | B17: P1 lever
A18: 4. Forward year / buyback | B18: minor
A19: Top two bars are both the SAMR scenario -> the edge is the regulatory/valuation outcome, not operating differentiation.
A21: FX flex — FY2027E base PT (USD)
A22: USD/CNY | B22: 7.1 | C22: 6.9 | D22: 6.76 | E22: 6.6 | F22: 6.4
A23: Base PT (USD) | B23: ='4. Scenarios'!C30*'4. Scenarios'!C9/7.1 -> 58.243 | C23: ='4. Scenarios'!C30*'4. Scenarios'!C9/6.9 -> 59.931203 | D23: ='4. Scenarios'!C30*'4. Scenarios'!C9/6.76 -> 61.172382 | E23: ='4. Scenarios'!C30*'4. Scenarios'!C9/6.6 -> 62.655349 | F23: ='4. Scenarios'!C30*'4. Scenarios'!C9/6.4 -> 64.613328
A24: Note: current spot 6.76 (highlighted). A severe-SAMR bear could coincide with yuan weakness (toward 7.1),
A25: deepening the USD downside - so part of the bear's cushion is FX, itself a variable. Flagged for Phase 12.
