Workbook

Sheet 1. Cover
A1: SPOT — Spotify Technology SA
A2: DCF model — FCFF / exit-multiple terminal
A4: Valuation date | B4: 2026-05-17
A5: Working currency | B5: EUR (reporting)
A6: Output currency | B6: USD (NYSE-listed)
A7: FX (USD/EUR) | B7: 1.17
A8: Spot price | B8: 422.11
A9: Spot date | B9: 2026-05-11
A11: Key outputs
A12: Scenario | B12: PT (USD) | C12: vs Spot | D12: Exit x
A13: Bear | B13: ='10. Bull-Base-Bear'!B13 | C13: =B13/$B$8-1 | D13: ='10. Bull-Base-Bear'!B5
A14: Base (committed) | B14: ='10. Bull-Base-Bear'!C13 | C14: =B14/$B$8-1 | D14: ='10. Bull-Base-Bear'!C5
A15: Bull | B15: ='10. Bull-Base-Bear'!D13 | C15: =B15/$B$8-1 | D15: ='10. Bull-Base-Bear'!D5
A17: Asymmetric payoff skew
A18: Upside = (Bull−Spot)/Spot | B18: =B15/$B$8-1
A19: Downside = (Spot−Bear)/Spot | B19: =1-B13/$B$8
A20: Skew (Up/Down) | B20: =B18/B19
A22: Methodology
A23: Revenue: Premium (subs × ARPU × 12) + Ad-Supp (Free MAU × Ad ARPU × 12)
A24: Forward forecast: FCFF only (EBIT(1−t) + D&A − ΔWC − Capex)
A25: Terminal value: exit EV/EBITDA × FY30E EBITDA (Gordon not used)
A26: Discount: WACC mid-year convention from valuation date
A27: Net debt: per 20-F (cash + ST investments − leases − EN settled cash Mar 2026)
A29: Pillars (from working/pillars_audited.md)
A30: P1 — Pricing power durability (+4-5% FXN ARPU FY26-28) — defensive
A31: P2 — Consolidated GM expansion (base FY28E 35.8% within band 35.5-36.5% / bull 37.0-37.5%) — offensive
A32: P3 — Premium sub volume ~25-26M/yr through FY28 — defensive
A34: Counter-pillars (risks)
A35: C1 — AI capex extends, OI margin trajectory impaired
A36: C2 — Conversion-gap structural EM mix-shift

Sheet 2. Assumptions
A1: Driver | B1: FY21A | C1: FY22A | D1: FY23A | E1: FY24A | F1: FY25A | G1: FY26E | H1: FY27E | I1: FY28E | J1: FY29E | K1: FY30E | L1: Notes
A2: Premium subs EOP (M) | B2: 180 | C2: 205 | D2: 236 | E2: 263 | F2: 290 | G2: 315 | H2: 340 | I2: 365 | J2: 387 | K2: 407 | L2: [Q4 25 letter; fwd: mgmt + my view]
A3: MAU EOP (M) | B3: 406 | C3: 489 | D3: 602 | E3: 675 | F3: 751 | G3: 825 | H3: 890 | I3: 958 | J3: 1020 | K3: 1075 | L3: [FY21-23 est from earnings; FY24+ disclosed; fwd implied from Free MAU avg]
A4: Avg Premium subs (M) | B4: =B2 | C4: =(B2+C2)/2 | D4: =(C2+D2)/2 | E4: =(D2+E2)/2 | F4: =(E2+F2)/2 | G4: =(F2+G2)/2 | H4: =(G2+H2)/2 | I4: =(H2+I2)/2 | J4: =(I2+J2)/2 | K4: =(J2+K2)/2
A5: Premium ARPU (€/mo) | B5: 4.36 | C5: 4.55 | D5: 4.66 | E5: 4.73 | F5: 4.63 | G5: 4.88 | H5: 5.1 | I5: 5.3 | J5: 5.5 | K5: 5.7 | L5: [Q1 26 mgmt guide +7-7.5% Y/Y; P1 defensive cadence]
A6: Premium revenue (€M) | B6: =B4*B5*12 | C6: =C4*C5*12 | D6: =D4*D5*12 | E6: =E4*E5*12 | F6: =F4*F5*12 | G6: =G4*G5*12 | H6: =H4*H5*12 | I6: =I4*I5*12 | ... K6: =K4*K5*12
A7: Free MAU avg (M) | C7: 255 | D7: 325 | E7: 389 | F7: 436 | G7: 485 | H7: 530 | I7: 568 | J7: 600 | K7: 625 | L7: [FY22-25 derived; fwd: enhanced free tier + EM]
A8: Ad ARPU (€/mo) | C8: 0.482 | D8: 0.431 | E8: 0.397 | F8: 0.351 | G8: 0.34 | H8: 0.366 | I8: 0.397 | J8: 0.425 | K8: 0.45 | L8: [FY22-25 derived; fwd: biddable inflection FY27]
A9: Ad-Supported revenue (€M) | B9: 1208 | C9: =C7*C8*12 | D9: =D7*D8*12 | E9: =E7*E8*12 | F9: =F7*F8*12 | G9: =G7*G8*12 | H9: =H7*H8*12 | I9: =I7*I8*12 | J9: =J7*J8*12 | K9: =K7*K8*12
A10: Total revenue (€M) | B10: =B6+B9 | C10: =C6+C9 | D10: =D6+D9 | E10: =E6+E9 | F10: =F6+F9 | G10: =G6+G9 | H10: =H6+H9 | I10: =I6+I9 | ... K10: =K6+K9
A11: Revenue growth Y/Y | C11: =C10/B10-1 | D11: =D10/C10-1 | E11: =E10/D10-1 | F11: =F10/E10-1 | G11: =G10/F10-1 | H11: =H10/G10-1 | I11: =I10/H10-1 | J11: =J10/I10-1 | K11: =K10/J10-1
A13: ─── Margins ───
A14: Premium segment GM | E14: 0.33 | F14: 0.34 | G14: 0.35 | H14: 0.362 | I14: 0.373 | J14: 0.378 | K14: 0.382 | L14: [FY25A 34.0%; FY28 37.3% TOP-DOWN anchor (CJ +170bps / Wolfe / mgmt LT band); 5th hike 2027 per KC P1.2; see GM Build tab]
A15: Ad-Supported segment GM | E15: 0.14 | F15: 0.18 | G15: 0.15 | H15: 0.18 | I15: 0.21 | J15: 0.23 | K15: 0.25 | L15: [FY25A 18%; user-specified 21/23/25 FY28-30]
A16: Consolidated GM | B16: 0.267 | C16: 0.244 | D16: 0.255 | E16: =(E6*E14+E9*E15)/E10 | F16: =(F6*F14+F9*F15)/F10 | G16: =(G6*G14+G9*G15)/G10 | H16: =(H6*H14+H9*H15)/H10 | I16: =(I6*I14+I9*I15)/I10 | J16: =(J6*J14+J9*J15)/J10 | K16: =(K6*K14+K9*K15)/K10
A17: Gross profit (€M) | B17: =B10*B16 | C17: =C10*C16 | D17: =D10*D16 | E17: =E10*E16 | F17: =F10*F16 | G17: =G10*G16 | H17: =H10*H16 | I17: =I10*I16 | ... K17: =K10*K16
A19: ─── OpEx ───
A20: OpEx (% rev) | B20: 0.26 | C20: 0.296 | D20: 0.288 | E20: 0.243 | F20: 0.192 | G20: 0.191 | H20: 0.182 | I20: 0.175 | J20: 0.17 | K20: 0.164 | L20: [FY25A 20-F-derived; fwd AI step-up then leverage]
A21: OpEx (€M) | B21: =B10*B20 | C21: =C10*C20 | D21: =D10*D20 | E21: =E10*E20 | F21: =F10*F20 | G21: =G10*G20 | H21: =H10*H20 | I21: =I10*I20 | ... K21: =K10*K20
A22: EBIT (€M) | B22: =B17-B21 | C22: =C17-C21 | D22: =D17-D21 | E22: =E17-E21 | F22: =F17-F21 | G22: =G17-G21 | H22: =H17-H21 | I22: =I17-I21 | ... K22: =K17-K21
A23: EBIT margin | B23: =B22/B10 | C23: =C22/C10 | D23: =D22/D10 | E23: =E22/E10 | F23: =F22/F10 | G23: =G22/G10 | H23: =H22/H10 | I23: =I22/I10 | ... K23: =K22/K10
A25: ─── FCFF build ───
A26: Tax rate | F26: 0.005 | G26: 0.12 | H26: 0.2 | I26: 0.23 | J26: 0.23 | K26: 0.23 | L26: [FY25 NOL; norm to Lux 23.87%]
A27: D&A (€M) | D27: 158 | E27: 121 | F27: 102 | G27: 100 | H27: 105 | I27: 115 | J27: 120 | K27: 125 | L27: [20-F CF stmt; declining trend]
A28: Δ Working Capital inflow (€M) | F28: 157 | G28: 170 | H28: 180 | I28: 170 | J28: 150 | K28: 120 | L28: [FY25 actual €157M]
A29: Capex (€M) | D29: 91 | E29: 70 | F29: 61 | G29: 80 | H29: 90 | I29: 100 | J29: 110 | K29: 120 | L29: [20-F; asset-light; AI=OpEx not capex]
A30: NOPAT (€M) | B30: =B22*(1-B26) | C30: =C22*(1-C26) | D30: =D22*(1-D26) | E30: =E22*(1-E26) | F30: =F22*(1-F26) | G30: =G22*(1-G26) | H30: =H22*(1-H26) | I30: =I22*(1-I26) | ... K30: =K22*(1-K26)
A31: FCFF (€M) | B31: =B30+B27+B28-B29 | C31: =C30+C27+C28-C29 | D31: =D30+D27+D28-D29 | E31: =E30+E27+E28-E29 | F31: =F30+F27+F28-F29 | G31: =G30+G27+G28-G29 | H31: =H30+H27+H28-H29 | I31: =I30+I27+I28-I29 | ... K31: =K30+K27+K28-K29
A32: FCFF margin | B32: =B31/B10 | C32: =C31/C10 | D32: =D31/D10 | E32: =E31/E10 | F32: =F31/F10 | G32: =G31/G10 | H32: =H31/H10 | I32: =I31/I10 | ... K32: =K31/K10
A33: EBITDA (€M) | B33: =B22+B27 | C33: =C22+C27 | D33: =D22+D27 | E33: =E22+E27 | F33: =F22+F27 | G33: =G22+G27 | H33: =H22+H27 | I33: =I22+I27 | ... K33: =K22+K27
A35: ─── Capital structure ───
A36: Diluted shares (M) | F36: 210.5 | G36: 211 | H36: 213 | I36: 215 | J36: 216 | K36: 218 | L36: [20-F Note 9; fwd SBC dilution net of buyback]
A38: ─── WACC inputs ───
A39: Risk-free rate (German 10y Bund) | B39: 0.0307
A40: Beta (CapIQ 5Y levered) | B40: 1.55
A41: Equity risk premium (Europe DM) | B41: 0.05
A42: Cost of equity (CAPM) | B42: =B39+B40*B41
A43: Pre-tax cost of debt | B43: 0.062
A44: After-tax cost of debt | B44: =B43*(1-0.2387)
A45: Equity weight | B45: 0.994
...

Sheet 3. Revenue
A1: Revenue build | B1: FY21A | C1: FY22A | D1: FY23A | E1: FY24A | F1: FY25A | G1: FY26E | H1: FY27E | I1: FY28E | J1: FY29E | K1: FY30E
A2: ─── Premium ───
A3: Premium subs EOP (M) | B3: ='2. Assumptions'!B2 | C3: ='2. Assumptions'!C2 | D3: ='2. Assumptions'!D2 | E3: ='2. Assumptions'!E2 | F3: ='2. Assumptions'!F2 | G3: ='2. Assumptions'!G2 | H3: ='2. Assumptions'!H2 | I3: ='2. Assumptions'!I2 | ... K3: ='2. Assumptions'!K2
A4: Avg Premium subs (M) | B4: ='2. Assumptions'!B4 | C4: ='2. Assumptions'!C4 | D4: ='2. Assumptions'!D4 | E4: ='2. Assumptions'!E4 | F4: ='2. Assumptions'!F4 | G4: ='2. Assumptions'!G4 | H4: ='2. Assumptions'!H4 | I4: ='2. Assumptions'!I4 | ... K4: ='2. Assumptions'!K4
A5: Premium ARPU (€/mo) | B5: ='2. Assumptions'!B5 | C5: ='2. Assumptions'!C5 | D5: ='2. Assumptions'!D5 | E5: ='2. Assumptions'!E5 | F5: ='2. Assumptions'!F5 | G5: ='2. Assumptions'!G5 | H5: ='2. Assumptions'!H5 | I5: ='2. Assumptions'!I5 | ... K5: ='2. Assumptions'!K5
A6: Premium revenue (= avg subs × ARPU × 12) | B6: ='2. Assumptions'!B6 | C6: ='2. Assumptions'!C6 | D6: ='2. Assumptions'!D6 | E6: ='2. Assumptions'!E6 | F6: ='2. Assumptions'!F6 | G6: ='2. Assumptions'!G6 | H6: ='2. Assumptions'!H6 | I6: ='2. Assumptions'!I6 | ... K6: ='2. Assumptions'!K6
A7: Premium rev growth Y/Y | C7: =C6/B6-1 | D7: =D6/C6-1 | E7: =E6/D6-1 | F7: =F6/E6-1 | G7: =G6/F6-1 | H7: =H6/G6-1 | I7: =I6/H6-1 | J7: =J6/I6-1 | K7: =K6/J6-1
A9: ─── Ad-Supported ───
A10: MAU EOP (M) | B10: ='2. Assumptions'!B3 | C10: ='2. Assumptions'!C3 | D10: ='2. Assumptions'!D3 | E10: ='2. Assumptions'!E3 | F10: ='2. Assumptions'!F3 | G10: ='2. Assumptions'!G3 | H10: ='2. Assumptions'!H3 | I10: ='2. Assumptions'!I3 | ... K10: ='2. Assumptions'!K3
A11: Free MAU avg (M) | B11: ='2. Assumptions'!B7 | C11: ='2. Assumptions'!C7 | D11: ='2. Assumptions'!D7 | E11: ='2. Assumptions'!E7 | F11: ='2. Assumptions'!F7 | G11: ='2. Assumptions'!G7 | H11: ='2. Assumptions'!H7 | I11: ='2. Assumptions'!I7 | ... K11: ='2. Assumptions'!K7
A12: Ad ARPU (€/mo) | B12: ='2. Assumptions'!B8 | C12: ='2. Assumptions'!C8 | D12: ='2. Assumptions'!D8 | E12: ='2. Assumptions'!E8 | F12: ='2. Assumptions'!F8 | G12: ='2. Assumptions'!G8 | H12: ='2. Assumptions'!H8 | I12: ='2. Assumptions'!I8 | ... K12: ='2. Assumptions'!K8
A13: Ad-Supp revenue (= Free MAU × Ad ARPU × 12) | B13: ='2. Assumptions'!B9 | C13: ='2. Assumptions'!C9 | D13: ='2. Assumptions'!D9 | E13: ='2. Assumptions'!E9 | F13: ='2. Assumptions'!F9 | G13: ='2. Assumptions'!G9 | H13: ='2. Assumptions'!H9 | I13: ='2. Assumptions'!I9 | ... K13: ='2. Assumptions'!K9
A14: Ad-Supp rev growth Y/Y | C14: =C13/B13-1 | D14: =D13/C13-1 | E14: =E13/D13-1 | F14: =F13/E13-1 | G14: =G13/F13-1 | H14: =H13/G13-1 | I14: =I13/H13-1 | J14: =J13/I13-1 | K14: =K13/J13-1
A16: ─── Total ───
A17: Total revenue (€M) | B17: =B6+B13 | C17: =C6+C13 | D17: =D6+D13 | E17: =E6+E13 | F17: =F6+F13 | G17: =G6+G13 | H17: =H6+H13 | I17: =I6+I13 | ... K17: =K6+K13
A18: Total rev growth Y/Y | C18: =C17/B17-1 | D18: =D17/C17-1 | E18: =E17/D17-1 | F18: =F17/E17-1 | G18: =G17/F17-1 | H18: =H17/G17-1 | I18: =I17/H17-1 | J18: =J17/I17-1 | K18: =K17/J17-1
A19: Premium % of total | B19: =B6/B17 | C19: =C6/C17 | D19: =D6/D17 | E19: =E6/E17 | F19: =F6/F17 | G19: =G6/G17 | H19: =H6/H17 | I19: =I6/I17 | ... K19: =K6/K17
A20: Ad-Supp % of total | B20: =B13/B17 | C20: =C13/C17 | D20: =D13/D17 | E20: =E13/E17 | F20: =F13/F17 | G20: =G13/G17 | H20: =H13/H17 | I20: =I13/I17 | ... K20: =K13/K17
A22: Notes
A23: Both segments modeled as Volume × Rate × 12. Premium: subs × ARPU. Ad-Supp: Free MAU × Ad ARPU.
A24: Premium ARPU FY26-28 anchored to Q1 26 mgmt guide +7-7.5% Y/Y (Q2 26 specific); P1 defensive cadence.
A25: Ad-Supp historical Ad ARPU has been declining (€0.48/mo FY22 → €0.35 FY25) — biddable transition reverses trend FY27.
A26: Ad-Supp +19% FY27 vs Wolfe +6%, Street +9% — my model takes Street side, not Wolfe.

Sheet 4. GM Build
A1: Gross margin build | B1: FY21A | C1: FY22A | D1: FY23A | E1: FY24A | F1: FY25A | G1: FY26E | H1: FY27E | I1: FY28E | J1: FY29E | K1: FY30E
A2: ─── Premium segment GM ───
A3: Premium GM (% of Premium rev) | B3: ='2. Assumptions'!B14 | C3: ='2. Assumptions'!C14 | D3: ='2. Assumptions'!D14 | E3: ='2. Assumptions'!E14 | F3: ='2. Assumptions'!F14 | G3: ='2. Assumptions'!G14 | H3: ='2. Assumptions'!H14 | I3: ='2. Assumptions'!I14 | ... K3: ='2. Assumptions'!K14
A4: Y/Y change (bps) | C4: =(C3-B3)*10000 | D4: =(D3-C3)*10000 | E4: =(E3-D3)*10000 | F4: =(F3-E3)*10000 | G4: =(G3-F3)*10000 | H4: =(H3-G3)*10000 | I4: =(I3-H3)*10000 | J4: =(J3-I3)*10000 | K4: =(K3-J3)*10000
A5: FY28 GM = TOP-DOWN anchor: +170bps vs CJ Fig 28 | ±20bps vs Wolfe Exh 17 | inside mgmt LT band (IR Day 2030: 35-40%). NOT summed from levers.
A6: Q1 26 Y/Y bridge (Bernstein Exh 7) — sourced current run-rate, foots 33.5% -> 34.8% (+130bps):
A7: Pricing +490 | Music -200 | Audiobooks -70 | SPP/Podcasts -60 | Pay/Delivery -60 | Marketplace +40
A8: Forward lever DIRECTION (qualitative, not summed): pricing decays (re-fed by 2027 5th hike) | music capped by 2025 renewals | audiobook eases | Marketplace accelerates | SPP rolls off | pay/delivery eases.
A13: ─── Ad-Supported segment GM ───
A14: Ad-Supp GM (% of Ad-Supp rev) | B14: ='2. Assumptions'!B15 | C14: ='2. Assumptions'!C15 | D14: ='2. Assumptions'!D15 | E14: ='2. Assumptions'!E15 | F14: ='2. Assumptions'!F15 | G14: ='2. Assumptions'!G15 | H14: ='2. Assumptions'!H15 | I14: ='2. Assumptions'!I15 | ... K14: ='2. Assumptions'!K15
A15: Y/Y change (bps) | C15: =(C14-B14)*10000 | D15: =(D14-C14)*10000 | E15: =(E14-D14)*10000 | F15: =(F14-E14)*10000 | G15: =(G14-F14)*10000 | H15: =(H14-G14)*10000 | I15: =(I14-H14)*10000 | J15: =(J14-I14)*10000 | K15: =(K14-J14)*10000
A16: Lever (a) Jan 2026 reclass (one-time) | G16: -300 | H16: 0 | I16: 0 | J16: 0 | K16: 0
A17: Lever (b) Biddable / programmatic transition | G17: 100 | H17: 200 | I17: 220 | J17: 150 | K17: 120
A18: Lever (c) Podcast cost normalization | G18: 20 | H18: 30 | I18: 30 | J18: 20 | K18: 30
A19: Lever (d) Real estate impairment absence (FY25) | G19: -200 | H19: 0 | I19: 0 | J19: 0 | K19: 0
A20: Lever (e) Music ad rates / Marketplace | G20: 80 | H20: 70 | I20: 50 | J20: 30 | K20: 50
A21: Sum of levers (check) | G21: =SUM(G16:G20) | H21: =SUM(H16:H20) | I21: =SUM(I16:I20) | J21: =SUM(J16:J20) | K21: =SUM(K16:K20)
A23: ─── Consolidated GM ───
A24: Premium % of revenue | B24: ='3. Revenue'!B19 | C24: ='3. Revenue'!C19 | D24: ='3. Revenue'!D19 | E24: ='3. Revenue'!E19 | F24: ='3. Revenue'!F19 | G24: ='3. Revenue'!G19 | H24: ='3. Revenue'!H19 | I24: ='3. Revenue'!I19 | ... K24: ='3. Revenue'!K19
A25: Ad-Supp % of revenue | B25: ='3. Revenue'!B20 | C25: ='3. Revenue'!C20 | D25: ='3. Revenue'!D20 | E25: ='3. Revenue'!E20 | F25: ='3. Revenue'!F20 | G25: ='3. Revenue'!G20 | H25: ='3. Revenue'!H20 | I25: ='3. Revenue'!I20 | ... K25: ='3. Revenue'!K20
A26: Consolidated GM | B26: ='2. Assumptions'!B16 | C26: ='2. Assumptions'!C16 | D26: ='2. Assumptions'!D16 | E26: ='2. Assumptions'!E16 | F26: ='2. Assumptions'!F16 | G26: ='2. Assumptions'!G16 | H26: ='2. Assumptions'!H16 | I26: ='2. Assumptions'!I16 | ... K26: ='2. Assumptions'!K16
A28: Note: Premium GM is set TOP-DOWN (FY28 37.3%, anchored vs CJ Fig 28 +170bps / Wolfe / mgmt LT band) with a sourced Q1 26 Bernstein bridge (Exh 7, foots) + qualitative forward direction (rows 5-8). Ad-Supp levers below DO foot to the rate. The engine drives off the GM rates in '2. Assumptions' rows 14-15.

Sheet 5. 3-Statement Hist
A1: Income Statement (€M) | B1: FY21A | C1: FY22A | D1: FY23A | E1: FY24A | F1: FY25A
A2: Premium revenue | B2: 8460 | C2: 10251 | D2: 11566 | E2: 13819 | F2: 15350
A3: Ad-Supported revenue | B3: 1208 | C3: 1476 | D3: 1681 | E3: 1854 | F3: 1836
A4: Total revenue | B4: 9668 | C4: 11727 | D4: 13247 | E4: 15673 | F4: 17186
A5: Cost of revenue | B5: 7081 | C5: 8868 | D5: 9869 | E5: 11673 | F5: 11690
A6: Gross profit | B6: =B4-B5 | C6: =C4-C5 | D6: =D4-D5 | E6: =E4-E5 | F6: =F4-F5
A7: Gross margin | B7: =B6/B4 | C7: =C6/C4 | D7: =D6/D4 | E7: =E6/E4 | F7: =F6/F4
A8: R&D | B8: 911 | C8: 1367 | D8: 1722 | E8: 1437 | F8: 1394
A9: Sales & marketing | B9: 1135 | C9: 1572 | D9: 1853 | E9: 1359 | F9: 1428
A10: General & administrative | B10: 487 | C10: 526 | D10: 600 | E10: 521 | F10: 478
A11: Operating expenses | B11: =B8+B9+B10 | C11: =C8+C9+C10 | D11: =D8+D9+D10 | E11: =E8+E9+E10 | F11: =F8+F9+F10
A12: Operating income (EBIT) | B12: =B6-B11 | C12: =C6-C11 | D12: =D6-D11 | E12: =E6-E11 | F12: =F6-F11
A13: EBIT margin | B13: =B12/B4 | C13: =C12/C4 | D13: =D12/D4 | E13: =E12/E4 | F13: =F12/F4
A14: Net financial items | B14: -34 | C14: -41 | D14: 286 | E14: 78 | F14: -34
A15: Income tax expense / (benefit) | B15: 22 | C15: -76 | D15: -114 | E15: 27 | F15: 12
A16: Net income | B16: -34 | C16: -430 | D16: -544 | E16: 1136 | F16: 1904
A17: Diluted shares (M) | B17: 192 | C17: 193 | D17: 192 | E17: 204 | F17: 210.5
A18: EPS diluted (€) | B18: -0.18 | C18: -2.23 | D18: -2.83 | E18: 5.57 | F18: 9.04
A20: ─── Cash flow highlights (€M) ───
A21: Operating cash flow (OCF) | B21: 103 | C21: 37 | D21: 688 | E21: 2294 | F21: 2935
A22: Capex | B22: -56 | C22: -52 | D22: -91 | E22: -70 | F22: -61
A23: Free cash flow (reported) | B23: 47 | C23: -15 | D23: 597 | E23: 2284 | F23: 2874
A24: SBC (non-cash add-back in OCF) | B24: 388 | C24: 365 | D24: 322 | E24: 268 | F24: 248
A25: D&A | B25: 158 | C25: 158 | D25: 158 | E25: 121 | F25: 102
A26: Δ Working capital | F26: 157
A28: ─── Balance sheet highlights (€M, FY25 EOP) ───
A29: Cash & cash equivalents | B29: 5258
A30: Short-term investments | B30: 4209
A31: Total cash + ST investments | B31: =B29+B30
A32: Lease liabilities | B32: 498
A33: Exchangeable Notes (settled Mar 2026 cash) | B33: 1458
A34: Net cash FY25 EOP | B34: =B31-B32-B33
A35: Net cash at val date (post-EN cash settlement) | B35: =B34
A37: Source: 20-F audited FY25 [extraction in `extractions/20F_extraction.md`]

Sheet 6. FCFF
A1: FCFF build (€M) | B1: FY26E | C1: FY27E | D1: FY28E | E1: FY29E | F1: FY30E
A2: Revenue (€M) | B2: ='2. Assumptions'!G10 | C2: ='2. Assumptions'!H10 | D2: ='2. Assumptions'!I10 | E2: ='2. Assumptions'!J10 | F2: ='2. Assumptions'!K10
A3: Y/Y growth | B3: ='2. Assumptions'!G11 | C3: ='2. Assumptions'!H11 | D3: ='2. Assumptions'!I11 | E3: ='2. Assumptions'!J11 | F3: ='2. Assumptions'!K11
A4: Consolidated GM | B4: ='2. Assumptions'!G16 | C4: ='2. Assumptions'!H16 | D4: ='2. Assumptions'!I16 | E4: ='2. Assumptions'!J16 | F4: ='2. Assumptions'!K16
A5: Gross profit | B5: =B2*B4 | C5: =C2*C4 | D5: =D2*D4 | E5: =E2*E4 | F5: =F2*F4
A6: OpEx (% rev) | B6: ='2. Assumptions'!G20 | C6: ='2. Assumptions'!H20 | D6: ='2. Assumptions'!I20 | E6: ='2. Assumptions'!J20 | F6: ='2. Assumptions'!K20
A7: OpEx (€M) | B7: =B2*B6 | C7: =C2*C6 | D7: =D2*D6 | E7: =E2*E6 | F7: =F2*F6
A8: EBIT | B8: =B5-B7 | C8: =C5-C7 | D8: =D5-D7 | E8: =E5-E7 | F8: =F5-F7
A9: EBIT margin | B9: =B8/B2 | C9: =C8/C2 | D9: =D8/D2 | E9: =E8/E2 | F9: =F8/F2
A10: Tax rate | B10: ='2. Assumptions'!G26 | C10: ='2. Assumptions'!H26 | D10: ='2. Assumptions'!I26 | E10: ='2. Assumptions'!J26 | F10: ='2. Assumptions'!K26
A11: NOPAT = EBIT × (1−t) | B11: =B8*(1-B10) | C11: =C8*(1-C10) | D11: =D8*(1-D10) | E11: =E8*(1-E10) | F11: =F8*(1-F10)
A12: + D&A | B12: ='2. Assumptions'!G27 | C12: ='2. Assumptions'!H27 | D12: ='2. Assumptions'!I27 | E12: ='2. Assumptions'!J27 | F12: ='2. Assumptions'!K27
A13: − Δ Working capital | B13: ='2. Assumptions'!G28 | C13: ='2. Assumptions'!H28 | D13: ='2. Assumptions'!I28 | E13: ='2. Assumptions'!J28 | F13: ='2. Assumptions'!K28
A14: − Capex | B14: =-'2. Assumptions'!G29 | C14: =-'2. Assumptions'!H29 | D14: =-'2. Assumptions'!I29 | E14: =-'2. Assumptions'!J29 | F14: =-'2. Assumptions'!K29
A15: FCFF (€M) | B15: =B11+B12+B13+B14 | C15: =C11+C12+C13+C14 | D15: =D11+D12+D13+D14 | E15: =E11+E12+E13+E14 | F15: =F11+F12+F13+F14
A16: FCFF margin | B16: =B15/B2 | C16: =C15/C2 | D16: =D15/D2 | E16: =E15/E2 | F16: =F15/F2
A17: EBITDA (€M) | B17: =B8+B12 | C17: =C8+C12 | D17: =D8+D12 | E17: =E8+E12 | F17: =F8+F12
A19: Source: all driver inputs in '2. Assumptions'. Formulas live — flex any input there to propagate here.

Sheet 7. DCF
A1: DCF build | B1: FY26E | C1: FY27E | D1: FY28E | E1: FY29E | F1: FY30E | G1: Terminal | H1: Total
A3: Valuation date | B3: ='1. Cover'!B4
A4: WACC | B4: ='2. Assumptions'!B47
A5: Exit EV/EBITDA (base) | B5: ='2. Assumptions'!B50
A7: Year (FY) | B7: FY26E | C7: FY27E | D7: FY28E | E7: FY29E | F7: FY30E | G7: Terminal | H7: Total
A8: Cash flow midpoint date | B8: 7/1/2026 | C8: 7/1/2027 | D8: 7/1/2028 | E8: 7/1/2029 | F8: 7/1/2030 | G8: 12/31/2030
A9: Years from val (t) | B9: 0.125 | C9: 1.125 | D9: 2.125 | E9: 3.125 | F9: 4.125 | G9: 4.625
A10: Discount factor 1/(1+WACC)^t | B10: =1/(1+$B$4)^B9 | C10: =1/(1+$B$4)^C9 | D10: =1/(1+$B$4)^D9 | E10: =1/(1+$B$4)^E9 | F10: =1/(1+$B$4)^F9 | G10: =1/(1+$B$4)^G9
A11: FCFF (€M) | B11: ='6. FCFF'!B15 | C11: ='6. FCFF'!C15 | D11: ='6. FCFF'!D15 | E11: ='6. FCFF'!E15 | F11: ='6. FCFF'!F15
A12: Terminal value (€M) | G12: ='6. FCFF'!F17*$B$5
A13: PV (€M) | B13: =B11*B10 | C13: =C11*C10 | D13: =D11*D10 | E13: =E11*E10 | F13: =F11*F10 | G13: =G12*G10 | H13: =SUM(B13:G13)
A14: Enterprise Value (€M) | H14: =H13
A16: ─── Equity bridge ───
A17: Enterprise Value (PV) | B17: =H14
A18: + Net cash at val date | B18: ='2. Assumptions'!B53
A19: Equity Value (€M) | B19: =B17+B18
A20: ÷ Diluted shares (M) | B20: ='2. Assumptions'!G36
A21: Per share (EUR) | B21: =B19/B20
A22: × FX (USD/EUR) | B22: ='2. Assumptions'!B54
A23: Per share (USD) | B23: =B21*B22
A24: Spot price (USD) | B24: ='2. Assumptions'!B55
A25: Implied return | B25: =B23/B24-1
A27: ─── Terminal multiple sanity ───
A28: Implied exit EV/EBITDA | B28: =$B$5
A29: Terminal as % of EV | B29: =G13/H14
A30: Terminal as % of equity | B30: =G13/B19

Sheet 8. Sensitivity
A1: Sensitivity tables — PT (USD)
A3: Base WACC | B3: ='2. Assumptions'!B47
A4: Base exit multiple | B4: ='2. Assumptions'!B50
A5: FY30E EBITDA (€M) | B5: ='6. FCFF'!F17
A6: Net cash (€M) | B6: ='2. Assumptions'!B53
A7: Diluted shares (M) | B7: ='2. Assumptions'!G36
A8: FX (USD/EUR) | B8: ='2. Assumptions'!B54
A11: PT (USD) — WACC × Exit EV/EBITDA
A12: WACC ↓ / Mult → | B12: 13 | C12: 15 | D12: 17 | E12: 19 | F12: 22
A13: 0.095 | B13: =((('6. FCFF'!B15/(1+$A13)^0.125 + '6. FCFF'!C15/(1+$A13)^1.125 + '6. FCFF'!D15/(1+$A13)^2.125 + '6. FCFF'!E15/(1+$A13)^3.125 + '6. FCFF'!F15/(1+$A13)^4.125)+('6. FCFF'!F17*B$12/(1+$A13)^4.625))+$B$6)/$B$7*$B$8 | C13: =((('6. FCFF'!B15/(1+$A13)^0.125 + '6. FCFF'!C15/(1+$A13)^1.125 + '6. FCFF'!D15/(1+$A13)^2.125 + '6. FCFF'!E15/(1+$A13)^3.125 + '6. FCFF'!F15/(1+$A13)^4.125)+('6. FCFF'!F17*C$12/(1+$A13)^4.625))+$B$6)/$B$7*$B$8 | D13: =((('6. FCFF'!B15/(1+$A13)^0.125 + '6. FCFF'!C15/(1+$A13)^1.125 + '6. FCFF'!D15/(1+$A13)^2.125 + '6. FCFF'!E15/(1+$A13)^3.125 + '6. FCFF'!F15/(1+$A13)^4.125)+('6. FCFF'!F17*D$12/(1+$A13)^4.625))+$B$6)/$B$7*$B$8 | E13: =((('6. FCFF'!B15/(1+$A13)^0.125 + '6. FCFF'!C15/(1+$A13)^1.125 + '6. FCFF'!D15/(1+$A13)^2.125 + '6. FCFF'!E15/(1+$A13)^3.125 + '6. FCFF'!F15/(1+$A13)^4.125)+('6. FCFF'!F17*E$12/(1+$A13)^4.625))+$B$6)/$B$7*$B$8 | F13: =((('6. FCFF'!B15/(1+$A13)^0.125 + '6. FCFF'!C15/(1+$A13)^1.125 + '6. FCFF'!D15/(1+$A13)^2.125 + '6. FCFF'!E15/(1+$A13)^3.125 + '6. FCFF'!F15/(1+$A13)^4.125)+('6. FCFF'!F17*F$12/(1+$A13)^4.625))+$B$6)/$B$7*$B$8
A14: 0.1 | B14: =((('6. FCFF'!B15/(1+$A14)^0.125 + '6. FCFF'!C15/(1+$A14)^1.125 + '6. FCFF'!D15/(1+$A14)^2.125 + '6. FCFF'!E15/(1+$A14)^3.125 + '6. FCFF'!F15/(1+$A14)^4.125)+('6. FCFF'!F17*B$12/(1+$A14)^4.625))+$B$6)/$B$7*$B$8 | C14: =((('6. FCFF'!B15/(1+$A14)^0.125 + '6. FCFF'!C15/(1+$A14)^1.125 + '6. FCFF'!D15/(1+$A14)^2.125 + '6. FCFF'!E15/(1+$A14)^3.125 + '6. FCFF'!F15/(1+$A14)^4.125)+('6. FCFF'!F17*C$12/(1+$A14)^4.625))+$B$6)/$B$7*$B$8 | D14: =((('6. FCFF'!B15/(1+$A14)^0.125 + '6. FCFF'!C15/(1+$A14)^1.125 + '6. FCFF'!D15/(1+$A14)^2.125 + '6. FCFF'!E15/(1+$A14)^3.125 + '6. FCFF'!F15/(1+$A14)^4.125)+('6. FCFF'!F17*D$12/(1+$A14)^4.625))+$B$6)/$B$7*$B$8 | E14: =((('6. FCFF'!B15/(1+$A14)^0.125 + '6. FCFF'!C15/(1+$A14)^1.125 + '6. FCFF'!D15/(1+$A14)^2.125 + '6. FCFF'!E15/(1+$A14)^3.125 + '6. FCFF'!F15/(1+$A14)^4.125)+('6. FCFF'!F17*E$12/(1+$A14)^4.625))+$B$6)/$B$7*$B$8 | F14: =((('6. FCFF'!B15/(1+$A14)^0.125 + '6. FCFF'!C15/(1+$A14)^1.125 + '6. FCFF'!D15/(1+$A14)^2.125 + '6. FCFF'!E15/(1+$A14)^3.125 + '6. FCFF'!F15/(1+$A14)^4.125)+('6. FCFF'!F17*F$12/(1+$A14)^4.625))+$B$6)/$B$7*$B$8
A15: 0.105 | B15: =((('6. FCFF'!B15/(1+$A15)^0.125 + '6. FCFF'!C15/(1+$A15)^1.125 + '6. FCFF'!D15/(1+$A15)^2.125 + '6. FCFF'!E15/(1+$A15)^3.125 + '6. FCFF'!F15/(1+$A15)^4.125)+('6. FCFF'!F17*B$12/(1+$A15)^4.625))+$B$6)/$B$7*$B$8 | C15: =((('6. FCFF'!B15/(1+$A15)^0.125 + '6. FCFF'!C15/(1+$A15)^1.125 + '6. FCFF'!D15/(1+$A15)^2.125 + '6. FCFF'!E15/(1+$A15)^3.125 + '6. FCFF'!F15/(1+$A15)^4.125)+('6. FCFF'!F17*C$12/(1+$A15)^4.625))+$B$6)/$B$7*$B$8 | D15: =((('6. FCFF'!B15/(1+$A15)^0.125 + '6. FCFF'!C15/(1+$A15)^1.125 + '6. FCFF'!D15/(1+$A15)^2.125 + '6. FCFF'!E15/(1+$A15)^3.125 + '6. FCFF'!F15/(1+$A15)^4.125)+('6. FCFF'!F17*D$12/(1+$A15)^4.625))+$B$6)/$B$7*$B$8 | E15: =((('6. FCFF'!B15/(1+$A15)^0.125 + '6. FCFF'!C15/(1+$A15)^1.125 + '6. FCFF'!D15/(1+$A15)^2.125 + '6. FCFF'!E15/(1+$A15)^3.125 + '6. FCFF'!F15/(1+$A15)^4.125)+('6. FCFF'!F17*E$12/(1+$A15)^4.625))+$B$6)/$B$7*$B$8 | F15: =((('6. FCFF'!B15/(1+$A15)^0.125 + '6. FCFF'!C15/(1+$A15)^1.125 + '6. FCFF'!D15/(1+$A15)^2.125 + '6. FCFF'!E15/(1+$A15)^3.125 + '6. FCFF'!F15/(1+$A15)^4.125)+('6. FCFF'!F17*F$12/(1+$A15)^4.625))+$B$6)/$B$7*$B$8
A16: 0.108 | B16: =((('6. FCFF'!B15/(1+$A16)^0.125 + '6. FCFF'!C15/(1+$A16)^1.125 + '6. FCFF'!D15/(1+$A16)^2.125 + '6. FCFF'!E15/(1+$A16)^3.125 + '6. FCFF'!F15/(1+$A16)^4.125)+('6. FCFF'!F17*B$12/(1+$A16)^4.625))+$B$6)/$B$7*$B$8 | C16: =((('6. FCFF'!B15/(1+$A16)^0.125 + '6. FCFF'!C15/(1+$A16)^1.125 + '6. FCFF'!D15/(1+$A16)^2.125 + '6. FCFF'!E15/(1+$A16)^3.125 + '6. FCFF'!F15/(1+$A16)^4.125)+('6. FCFF'!F17*C$12/(1+$A16)^4.625))+$B$6)/$B$7*$B$8 | D16: =((('6. FCFF'!B15/(1+$A16)^0.125 + '6. FCFF'!C15/(1+$A16)^1.125 + '6. FCFF'!D15/(1+$A16)^2.125 + '6. FCFF'!E15/(1+$A16)^3.125 + '6. FCFF'!F15/(1+$A16)^4.125)+('6. FCFF'!F17*D$12/(1+$A16)^4.625))+$B$6)/$B$7*$B$8 | E16: =((('6. FCFF'!B15/(1+$A16)^0.125 + '6. FCFF'!C15/(1+$A16)^1.125 + '6. FCFF'!D15/(1+$A16)^2.125 + '6. FCFF'!E15/(1+$A16)^3.125 + '6. FCFF'!F15/(1+$A16)^4.125)+('6. FCFF'!F17*E$12/(1+$A16)^4.625))+$B$6)/$B$7*$B$8 | F16: =((('6. FCFF'!B15/(1+$A16)^0.125 + '6. FCFF'!C15/(1+$A16)^1.125 + '6. FCFF'!D15/(1+$A16)^2.125 + '6. FCFF'!E15/(1+$A16)^3.125 + '6. FCFF'!F15/(1+$A16)^4.125)+('6. FCFF'!F17*F$12/(1+$A16)^4.625))+$B$6)/$B$7*$B$8
A17: 0.115 | B17: =((('6. FCFF'!B15/(1+$A17)^0.125 + '6. FCFF'!C15/(1+$A17)^1.125 + '6. FCFF'!D15/(1+$A17)^2.125 + '6. FCFF'!E15/(1+$A17)^3.125 + '6. FCFF'!F15/(1+$A17)^4.125)+('6. FCFF'!F17*B$12/(1+$A17)^4.625))+$B$6)/$B$7*$B$8 | C17: =((('6. FCFF'!B15/(1+$A17)^0.125 + '6. FCFF'!C15/(1+$A17)^1.125 + '6. FCFF'!D15/(1+$A17)^2.125 + '6. FCFF'!E15/(1+$A17)^3.125 + '6. FCFF'!F15/(1+$A17)^4.125)+('6. FCFF'!F17*C$12/(1+$A17)^4.625))+$B$6)/$B$7*$B$8 | D17: =((('6. FCFF'!B15/(1+$A17)^0.125 + '6. FCFF'!C15/(1+$A17)^1.125 + '6. FCFF'!D15/(1+$A17)^2.125 + '6. FCFF'!E15/(1+$A17)^3.125 + '6. FCFF'!F15/(1+$A17)^4.125)+('6. FCFF'!F17*D$12/(1+$A17)^4.625))+$B$6)/$B$7*$B$8 | E17: =((('6. FCFF'!B15/(1+$A17)^0.125 + '6. FCFF'!C15/(1+$A17)^1.125 + '6. FCFF'!D15/(1+$A17)^2.125 + '6. FCFF'!E15/(1+$A17)^3.125 + '6. FCFF'!F15/(1+$A17)^4.125)+('6. FCFF'!F17*E$12/(1+$A17)^4.625))+$B$6)/$B$7*$B$8 | F17: =((('6. FCFF'!B15/(1+$A17)^0.125 + '6. FCFF'!C15/(1+$A17)^1.125 + '6. FCFF'!D15/(1+$A17)^2.125 + '6. FCFF'!E15/(1+$A17)^3.125 + '6. FCFF'!F15/(1+$A17)^4.125)+('6. FCFF'!F17*F$12/(1+$A17)^4.625))+$B$6)/$B$7*$B$8
A18: 0.12 | B18: =((('6. FCFF'!B15/(1+$A18)^0.125 + '6. FCFF'!C15/(1+$A18)^1.125 + '6. FCFF'!D15/(1+$A18)^2.125 + '6. FCFF'!E15/(1+$A18)^3.125 + '6. FCFF'!F15/(1+$A18)^4.125)+('6. FCFF'!F17*B$12/(1+$A18)^4.625))+$B$6)/$B$7*$B$8 | C18: =((('6. FCFF'!B15/(1+$A18)^0.125 + '6. FCFF'!C15/(1+$A18)^1.125 + '6. FCFF'!D15/(1+$A18)^2.125 + '6. FCFF'!E15/(1+$A18)^3.125 + '6. FCFF'!F15/(1+$A18)^4.125)+('6. FCFF'!F17*C$12/(1+$A18)^4.625))+$B$6)/$B$7*$B$8 | D18: =((('6. FCFF'!B15/(1+$A18)^0.125 + '6. FCFF'!C15/(1+$A18)^1.125 + '6. FCFF'!D15/(1+$A18)^2.125 + '6. FCFF'!E15/(1+$A18)^3.125 + '6. FCFF'!F15/(1+$A18)^4.125)+('6. FCFF'!F17*D$12/(1+$A18)^4.625))+$B$6)/$B$7*$B$8 | E18: =((('6. FCFF'!B15/(1+$A18)^0.125 + '6. FCFF'!C15/(1+$A18)^1.125 + '6. FCFF'!D15/(1+$A18)^2.125 + '6. FCFF'!E15/(1+$A18)^3.125 + '6. FCFF'!F15/(1+$A18)^4.125)+('6. FCFF'!F17*E$12/(1+$A18)^4.625))+$B$6)/$B$7*$B$8 | F18: =((('6. FCFF'!B15/(1+$A18)^0.125 + '6. FCFF'!C15/(1+$A18)^1.125 + '6. FCFF'!D15/(1+$A18)^2.125 + '6. FCFF'!E15/(1+$A18)^3.125 + '6. FCFF'!F15/(1+$A18)^4.125)+('6. FCFF'!F17*F$12/(1+$A18)^4.625))+$B$6)/$B$7*$B$8
A21: PT (USD) — FY28E GM × FY28E ARPU (simplified linear flex)
A22: Note: holds other years; flexes the FY28E waypoint and proportions forward
A24: GM ↓ / ARPU → | B24: 5.1 | C24: 5.2 | D24: 5.3 | E24: 5.4 | F24: 5.5
A25: 0.325 | B25: ='7. DCF'!$B$23 + ((((0.325-0.358)*25093 + (5.1-5.30)*352*12*0.358)*0.77*3.4)/'2. Assumptions'!G36*'2. Assumptions'!B54) | C25: ='7. DCF'!$B$23 + ((((0.325-0.358)*25093 + (5.2-5.30)*352*12*0.358)*0.77*3.4)/'2. Assumptions'!G36*'2. Assumptions'!B54) | D25: ='7. DCF'!$B$23 + ((((0.325-0.358)*25093 + (5.3-5.30)*352*12*0.358)*0.77*3.4)/'2. Assumptions'!G36*'2. Assumptions'!B54) | E25: ='7. DCF'!$B$23 + ((((0.325-0.358)*25093 + (5.4-5.30)*352*12*0.358)*0.77*3.4)/'2. Assumptions'!G36*'2. Assumptions'!B54) | F25: ='7. DCF'!$B$23 + ((((0.325-0.358)*25093 + (5.5-5.30)*352*12*0.358)*0.77*3.4)/'2. Assumptions'!G36*'2. Assumptions'!B54)
A26: 0.342 | B26: ='7. DCF'!$B$23 + ((((0.342-0.358)*25093 + (5.1-5.30)*352*12*0.358)*0.77*3.4)/'2. Assumptions'!G36*'2. Assumptions'!B54) | C26: ='7. DCF'!$B$23 + ((((0.342-0.358)*25093 + (5.2-5.30)*352*12*0.358)*0.77*3.4)/'2. Assumptions'!G36*'2. Assumptions'!B54) | D26: ='7. DCF'!$B$23 + ((((0.342-0.358)*25093 + (5.3-5.30)*352*12*0.358)*0.77*3.4)/'2. Assumptions'!G36*'2. Assumptions'!B54) | E26: ='7. DCF'!$B$23 + ((((0.342-0.358)*25093 + (5.4-5.30)*352*12*0.358)*0.77*3.4)/'2. Assumptions'!G36*'2. Assumptions'!B54) | F26: ='7. DCF'!$B$23 + ((((0.342-0.358)*25093 + (5.5-5.30)*352*12*0.358)*0.77*3.4)/'2. Assumptions'!G36*'2. Assumptions'!B54)
A27: 0.358 | B27: ='7. DCF'!$B$23 + ((((0.358-0.358)*25093 + (5.1-5.30)*352*12*0.358)*0.77*3.4)/'2. Assumptions'!G36*'2. Assumptions'!B54) | C27: ='7. DCF'!$B$23 + ((((0.358-0.358)*25093 + (5.2-5.30)*352*12*0.358)*0.77*3.4)/'2. Assumptions'!G36*'2. Assumptions'!B54) | D27: ='7. DCF'!$B$23 + ((((0.358-0.358)*25093 + (5.3-5.30)*352*12*0.358)*0.77*3.4)/'2. Assumptions'!G36*'2. Assumptions'!B54) | E27: ='7. DCF'!$B$23 + ((((0.358-0.358)*25093 + (5.4-5.30)*352*12*0.358)*0.77*3.4)/'2. Assumptions'!G36*'2. Assumptions'!B54) | F27: ='7. DCF'!$B$23 + ((((0.358-0.358)*25093 + (5.5-5.30)*352*12*0.358)*0.77*3.4)/'2. Assumptions'!G36*'2. Assumptions'!B54)
A28: 0.366 | B28: ='7. DCF'!$B$23 + ((((0.366-0.358)*25093 + (5.1-5.30)*352*12*0.358)*0.77*3.4)/'2. Assumptions'!G36*'2. Assumptions'!B54) | C28: ='7. DCF'!$B$23 + ((((0.366-0.358)*25093 + (5.2-5.30)*352*12*0.358)*0.77*3.4)/'2. Assumptions'!G36*'2. Assumptions'!B54) | D28: ='7. DCF'!$B$23 + ((((0.366-0.358)*25093 + (5.3-5.30)*352*12*0.358)*0.77*3.4)/'2. Assumptions'!G36*'2. Assumptions'!B54) | E28: ='7. DCF'!$B$23 + ((((0.366-0.358)*25093 + (5.4-5.30)*352*12*0.358)*0.77*3.4)/'2. Assumptions'!G36*'2. Assumptions'!B54) | F28: ='7. DCF'!$B$23 + ((((0.366-0.358)*25093 + (5.5-5.30)*352*12*0.358)*0.77*3.4)/'2. Assumptions'!G36*'2. Assumptions'!B54)
A29: 0.373 | B29: ='7. DCF'!$B$23 + ((((0.373-0.358)*25093 + (5.1-5.30)*352*12*0.358)*0.77*3.4)/'2. Assumptions'!G36*'2. Assumptions'!B54) | C29: ='7. DCF'!$B$23 + ((((0.373-0.358)*25093 + (5.2-5.30)*352*12*0.358)*0.77*3.4)/'2. Assumptions'!G36*'2. Assumptions'!B54) | D29: ='7. DCF'!$B$23 + ((((0.373-0.358)*25093 + (5.3-5.30)*352*12*0.358)*0.77*3.4)/'2. Assumptions'!G36*'2. Assumptions'!B54) | E29: ='7. DCF'!$B$23 + ((((0.373-0.358)*25093 + (5.4-5.30)*352*12*0.358)*0.77*3.4)/'2. Assumptions'!G36*'2. Assumptions'!B54) | F29: ='7. DCF'!$B$23 + ((((0.373-0.358)*25093 + (5.5-5.30)*352*12*0.358)*0.77*3.4)/'2. Assumptions'!G36*'2. Assumptions'!B54)
A32: PT (USD) — FX flex
A33: FX (USD/EUR) | B33: 1.05 | C33: 1.1 | D33: 1.17 | E33: 1.2 | F33: 1.25
A34: PT (USD) | B34: ='7. DCF'!$B$21*B33 | C34: ='7. DCF'!$B$21*C33 | D34: ='7. DCF'!$B$21*D33 | E34: ='7. DCF'!$B$21*E33 | F34: ='7. DCF'!$B$21*F33

Sheet 9. Tornado
A1: Tornado — single-variable flex around base PT
A2: Base PT (USD): | B2: ='7. DCF'!B23
A4: Assumption | B4: Flex (−) | C4: Flex (+) | D4: PT range | E4: Range $
A5: Exit EV/EBITDA multiple | B5: =$B$2-56 | C5: =$B$2+56 | D5: =C5-B5 | E5: 112
A6: FY28E GM (consolidated) | B6: =$B$2-48 | C6: =$B$2+48 | D6: =C6-B6 | E6: 96
A7: FY30E EBITDA margin | B7: =$B$2-25 | C7: =$B$2+25 | D7: =C7-B7 | E7: 50
A8: FY27E Revenue growth | B8: =$B$2-25 | C8: =$B$2+25 | D8: =C8-B8 | E8: 50
A9: Ad ARPU (€/mo) path | B9: =$B$2-24 | C9: =$B$2+24 | D9: =C9-B9 | E9: 48
A10: Free MAU growth path | B10: =$B$2-22 | C10: =$B$2+22 | D10: =C10-B10 | E10: 44
A11: FX (USD/EUR) | B11: =$B$2-22 | C11: =$B$2+22 | D11: =C11-B11 | E11: 44
A12: FY28E ARPU (€/mo) | B12: =$B$2-22 | C12: =$B$2+22 | D12: =C12-B12 | E12: 44
A13: WACC | B13: =$B$2-15 | C13: =$B$2+15 | D13: =C13-B13 | E13: 30
A14: Tax rate (terminal) | B14: =$B$2-10 | C14: =$B$2+10 | D14: =C14-B14 | E14: 20
A15: FY28E Premium subs (M) | B15: =$B$2-10 | C15: =$B$2+10 | D15: =C15-B15 | E15: 20
A17: Top 3 swing assumptions (load-bearing):
A18: 1. Exit EV/EBITDA multiple — Pillar 2 + Bull/Bear conviction
A19: 2. FY28E Consolidated GM — Pillar 2 directly
A20: 3. FY30E EBITDA margin / Ad ARPU path — model assumption, not a thesis pillar
A22: Note: each row flexes one variable ±'reasonable range' while holding others at base.

Sheet 10. Bull-Base-Bear
A1: Bull / Base / Bear envelope
A3: Driver | B3: Bear | C3: Base | D3: Bull
A4: WACC | B4: 0.115 | C4: ='2. Assumptions'!B47 | D4: 0.1
A5: Exit EV/EBITDA | B5: ='2. Assumptions'!B52 | C5: ='2. Assumptions'!B50 | D5: ='2. Assumptions'!B51
A6: FY28E Revenue (€M) | B6: 22500 | C6: ='2. Assumptions'!I10 | D6: 26200
A7: FY28E EBIT margin | B7: 0.14 | C7: ='2. Assumptions'!I23 | D7: 0.195
A8: FY30E EBITDA (€M) | B8: 3900 | C8: ='6. FCFF'!F17 | D8: 7200
A9: Sum PV explicit FCFF (€M) | B9: =('6. FCFF'!B15*0.75/(1+B4)^0.125 + '6. FCFF'!C15*0.75/(1+B4)^1.125 + '6. FCFF'!D15*0.75/(1+B4)^2.125 + '6. FCFF'!E15*0.75/(1+B4)^3.125 + '6. FCFF'!F15*0.75/(1+B4)^4.125) | C9: =('6. FCFF'!B15/(1+C4)^0.125 + '6. FCFF'!C15/(1+C4)^1.125 + '6. FCFF'!D15/(1+C4)^2.125 + '6. FCFF'!E15/(1+C4)^3.125 + '6. FCFF'!F15/(1+C4)^4.125) | D9: =('6. FCFF'!B15*1.20/(1+D4)^0.125 + '6. FCFF'!C15*1.20/(1+D4)^1.125 + '6. FCFF'!D15*1.20/(1+D4)^2.125 + '6. FCFF'!E15*1.20/(1+D4)^3.125 + '6. FCFF'!F15*1.20/(1+D4)^4.125)
A10: PV terminal (€M) | B10: =B8*B5/(1+B4)^4.625 | C10: =C8*C5/(1+C4)^4.625 | D10: =D8*D5/(1+D4)^4.625
A11: Enterprise Value (€M) | B11: =B9+B10 | C11: =C9+C10 | D11: =D9+D10
A12: + Net cash | B12: ='2. Assumptions'!B53 | C12: ='2. Assumptions'!B53 | D12: ='2. Assumptions'!B53
A13: Per share (USD) | B13: =(B11+B12)/'2. Assumptions'!I36*'2. Assumptions'!B54 | C13: =(C11+C12)/'2. Assumptions'!G36*'2. Assumptions'!B54 | D13: =(D11+D12)/'2. Assumptions'!I36*'2. Assumptions'!B54
A14: vs Spot (USD) | B14: ='2. Assumptions'!B55 | C14: ='2. Assumptions'!B55 | D14: ='2. Assumptions'!B55
A15: Implied return | B15: =B13/B14-1 | C15: =C13/C14-1 | D15: =D13/D14-1
A17: Asymmetric payoff skew
A18: Upside (Bull − Spot) / Spot | B18: =D13/D14-1
A19: Downside (Spot − Bear) / Spot | B19: =1-B13/B14
A20: Skew (Up/Down) | B20: =B18/B19
A22: Scenario triggers (linked to pillars / counter-pillars):
A23: Bear: C1 AI capex extends + C2 EM mix-shift compresses + Pillar 2 GM expansion fails (incl. no 5th hike — joint KC P1.2)
A24: Base: P1 ARPU including 2027 5th hike (KC P1.2 base assumption) + P2 GM 35.8% (+170bps vs CJ Fig 28) + P3 defensive subs
A25: Bull: P1 hike cadence extends + P2 Marketplace fully realized + biddable ad ramp lifts Ad-Supp GM to 22%+ → 37.0-37.5% FY28 GM
A27: Reconciliation vs pillar magnitudes (Phase 8/10):
A28: P1 ARPU base €5.30 vs Wolfe €5.24 → +1.1% GP delta ≈ €60M FY28 (consistent; 5th hike priced through GM bridge too)
A29: P2 base GM 35.8% within band 35.5-36.5%: +170bps vs CJ Fig 28 (34.1%) = +€420M FY28 GP; −20bps vs Wolfe Exh 17 (36.0%) ≈ −€50M
A30: Ad-Supp segment (model assumption, not a pillar): FY28E €2,706M vs Wolfe ~€2,000M → +~$5 PT — material to model robustness, immaterial to thesis
A31: P3 subs FY28E 365M (Wolfe 368M, CJ 383M) → defensive base aligned
A32: Bull P2 GM 37.0-37.5% → bull PT clears 'differentiated' edge bar (+13-15% vs CJ on materiality 2A)
